Workbook

Sheet LEIA-ME
A1: Fluxo de caixa da obra — mesmas abas do MODELO 05, agora com cálculo automático
A3: O que mudou em relação ao modelo original
A4: • As abas são as mesmas. A diferença é que nada precisa de ajuste manual: em cada aba de disciplina, o saldo
A5: (META EM INCC − INCORRIDO EM INCC) é distribuído nos meses futuros e convertido em R$ pelo INCC do corte; a linha DIFERENÇA fica zerada.
A6: • A coluna PREVISÃO (R$) agora é calculada. O que você digitava nela vai na coluna H 'PREVISÃO INFORMADA' e vira o peso
A7: de cada mês. Se a soma do que você digitou não fechar com o saldo, a ferramenta reescala (mostra o % de ajuste em K15).
A8: • Regra da curva (célula K16 de cada aba): itens DIRETOS com avanço físico realizado no Prevision abaixo do limite
A9: (VALOR POR PL!K7, hoje 10%) seguem a CURVA DO PREVISION (colunas M a O da aba). Os demais usam a coluna H;
A10: sem coluna H, também usam o Prevision. Para forçar uma fonte numa aba, use a célula K15.
A11: • DADOS HISTORICOS localiza cada grupo do ERP pelo NOME e cada mês pela DATA do cabeçalho (antes era por posição).
A13: Atualização mensal
A14: 1. "INCC-FGV": acrescente o índice do mês (mês no formato 01/mm/aaaa).
... A33: • Tabela, PREMISSAS e AUX.ESTRUTURA foram copiadas como estavam (somente valores), para consulta.

Sheet DASHBOARD
B2: ='VALOR POR PL'!$P$9&" · FLUXO DE CAIXA DA OBRA"
B3: ="Data de corte: "&CHOOSE(MONTH('VALOR POR PL'!$P$5),"Janeiro","Fevereiro","Março","Abril","Maio","Junho","Julho","Agosto","Setembro","Outubro","Novembro","Dezembro")&"/"&YEAR('VALOR POR PL'!$P$5)&" · Ano do retrato: "&'RETRATO 2027'!$D$5&" · Cenário: "&IF('VALOR POR PL'!$K$8="PADRÃO","padrão (curvas digitadas)","Prevision")&" · R$ nominais, com taxa de adm."
B5: PROJEÇÃO TOTAL | D5: REALIZADO ATÉ O CORTE | E5: % REALIZADO | F5: ="DESEMBOLSO EM "&'RETRATO 2027'!$D$5 | H5: SALDO A REALIZAR | I5: CONFERÊNCIA
B6: ='MODELO PARA BI'!E66 | D6: =SUMPRODUCT(('MODELO PARA BI'!$H$1:$CA$1<='VALOR POR PL'!$P$5)*'MODELO PARA BI'!$H$65:$CA$65) | E6: =IF(B6=0,0,D6/B6) | F6: =SUMPRODUCT((YEAR('MODELO PARA BI'!$H$1:$CA$1)='RETRATO 2027'!$D$5)*'MODELO PARA BI'!$H$65:$CA$65) | H6: =SUM('MODELO PARA BI'!$H$65:$CA$65)-D6 | I6: =IF(COUNTIF('VALOR POR PL'!$F$54:$F$59,"⚠*")=0,"✓ Tudo OK","⚠ "&COUNTIF('VALOR POR PL'!$F$54:$F$59,"⚠*")&" pendência(s)")
B7: com contingência | D7: incorrido no ERP | E7: da projeção | F7: realizado + previsto | H7: após a data de corte | I7: detalhes em VALOR POR PL
B10: REALIZADO (ATUAL)
B11: =CHOOSE(MONTH(DATE(YEAR('VALOR POR PL'!$P$5),MONTH('VALOR POR PL'!$P$5)+1,1)),"Janeiro","Fevereiro","Março","Abril","Maio","Junho","Julho","Agosto","Setembro","Outubro","Novembro","Dezembro")&"/"&YEAR(DATE(YEAR('VALOR POR PL'!$P$5),MONTH('VALOR POR PL'!$P$5)+1,1)) | H11: COMPOSIÇÃO DO ANO
B12: Ano | C12: Anual R$ | D12: Acumulado R$ | E12: Anual % | F12: Acumulado % | H12: Realizado R$ | I12: A realizar R$
B13: =YEAR('VALOR POR PL'!$P$6)+0 | C13: =SUMPRODUCT((YEAR('MODELO PARA BI'!$H$1:$CA$1)=B13)*'MODELO PARA BI'!$H$65:$CA$65) | D13: =C13 | E13: =IF($C$20=0,0,C13/$C$20) | F13: =IF($C$20=0,0,D13/$C$20) | H13: =SUMPRODUCT((YEAR('MODELO PARA BI'!$H$1:$CA$1)=B13)*('MODELO PARA BI'!$H$1:$CA$1<='VALOR POR PL'!$P$5)*'MODELO PARA BI'!$H$65:$CA$65) | I13: =C13-H13
B14: =YEAR('VALOR POR PL'!$P$6)+1 | C14: =SUMPRODUCT((YEAR('MODELO PARA BI'!$H$1:$CA$1)=B14)*'MODELO PARA BI'!$H$65:$CA$65) | D14: =D13+C14 | E14: =IF($C$20=0,0,C14/$C$20) | F14: =IF($C$20=0,0,D14/$C$20) | H14: =SUMPRODUCT((YEAR('MODELO PARA BI'!$H$1:$CA$1)=B14)*('MODELO PARA BI'!$H$1:$CA$1<='VALOR POR PL'!$P$5)*'MODELO PARA BI'!$H$65:$CA$65) | I14: =C14-H14
B15: =YEAR('VALOR POR PL'!$P$6)+2 | C15: =SUMPRODUCT((YEAR('MODELO PARA BI'!$H$1:$CA$1)=B15)*'MODELO PARA BI'!$H$65:$CA$65) | D15: =D14+C15 | E15: =IF($C$20=0,0,C15/$C$20) | F15: =IF($C$20=0,0,D15/$C$20) | H15: =SUMPRODUCT((YEAR('MODELO PARA BI'!$H$1:$CA$1)=B15)*('MODELO PARA BI'!$H$1:$CA$1<='VALOR POR PL'!$P$5)*'MODELO PARA BI'!$H$65:$CA$65) | I15: =C15-H15
B16: =YEAR('VALOR POR PL'!$P$6)+3 | C16: =SUMPRODUCT((YEAR('MODELO PARA BI'!$H$1:$CA$1)=B16)*'MODELO PARA BI'!$H$65:$CA$65) | D16: =D15+C16 | E16: =IF($C$20=0,0,C16/$C$20) | F16: =IF($C$20=0,0,D16/$C$20) | H16: =SUMPRODUCT((YEAR('MODELO PARA BI'!$H$1:$CA$1)=B16)*('MODELO PARA BI'!$H$1:$CA$1<='VALOR POR PL'!$P$5)*'MODELO PARA BI'!$H$65:$CA$65) | I16: =C16-H16
B17: =YEAR('VALOR POR PL'!$P$6)+4 | C17: =SUMPRODUCT((YEAR('MODELO PARA BI'!$H$1:$CA$1)=B17)*'MODELO PARA BI'!$H$65:$CA$65) | D17: =D16+C17 | E17: =IF($C$20=0,0,C17/$C$20) | F17: =IF($C$20=0,0,D17/$C$20) | H17: =SUMPRODUCT((YEAR('MODELO PARA BI'!$H$1:$CA$1)=B17)*('MODELO PARA BI'!$H$1:$CA$1<='VALOR POR PL'!$P$5)*'MODELO PARA BI'!$H$65:$CA$65) | I17: =C17-H17
B18: =YEAR('VALOR POR PL'!$P$6)+5 | C18: =SUMPRODUCT((YEAR('MODELO PARA BI'!$H$1:$CA$1)=B18)*'MODELO PARA BI'!$H$65:$CA$65) | D18: =D17+C18 | E18: =IF($C$20=0,0,C18/$C$20) | F18: =IF($C$20=0,0,D18/$C$20) | H18: =SUMPRODUCT((YEAR('MODELO PARA BI'!$H$1:$CA$1)=B18)*('MODELO PARA BI'!$H$1:$CA$1<='VALOR POR PL'!$P$5)*'MODELO PARA BI'!$H$65:$CA$65) | I18: =C18-H18
B19: =YEAR('VALOR POR PL'!$P$6)+6 | C19: =SUMPRODUCT((YEAR('MODELO PARA BI'!$H$1:$CA$1)=B19)*'MODELO PARA BI'!$H$65:$CA$65) | D19: =D18+C19 | E19: =IF($C$20=0,0,C19/$C$20) | F19: =IF($C$20=0,0,D19/$C$20) | H19: =SUMPRODUCT((YEAR('MODELO PARA BI'!$H$1:$CA$1)=B19)*('MODELO PARA BI'!$H$1:$CA$1<='VALOR POR PL'!$P$5)*'MODELO PARA BI'!$H$65:$CA$65) | I19: =C19-H19
B20: TOTAL | C20: =SUM(C13:C19) | E20: =SUM(E13:E19) | H20: =SUM(H13:H19) | I20: =SUM(I13:I19)
B21: Linha destacada = ano do retrato (RETRATO 2027!D5). Realizado = até a data de corte; a realizar = previsto depois dela.
B24: ="DESEMBOLSO EM "&'RETRATO 2027'!$D$5&" POR GRUPO"
B25: Grupo | D25: R$ | E25: % do ano | F25: Avanço financeiro
B26: Indiretos (01 a 11) | D26: =SUM('RETRATO 2027'!F12:F22) | E26: =IF($D$32=0,0,D26/$D$32) | F26: =IFERROR(SUMPRODUCT('RETRATO 2027'!J12:J22,'RETRATO 2027'!M12:M22)/SUM('RETRATO 2027'!M12:M22),0)
B27: Infraestrutura (12 a 16) | D27: =SUM('RETRATO 2027'!F24:F28) | E27: =IF($D$32=0,0,D27/$D$32) | F27: =IFERROR(SUMPRODUCT('RETRATO 2027'!J24:J28,'RETRATO 2027'!M24:M28)/SUM('RETRATO 2027'!M24:M28),0)
B28: Estrutura (17) | D28: =SUM('RETRATO 2027'!F30:F30) | E28: =IF($D$32=0,0,D28/$D$32) | F28: =IFERROR(SUMPRODUCT('RETRATO 2027'!J30:J30,'RETRATO 2027'!M30:M30)/SUM('RETRATO 2027'!M30:M30),0)
B29: Vedações, instalações e elevadores (18 a 24) | D29: =SUM('RETRATO 2027'!F31:F37) | E29: =IF($D$32=0,0,D29/$D$32) | F29: =IFERROR(SUMPRODUCT('RETRATO 2027'!J31:J37,'RETRATO 2027'!M31:M37)/SUM('RETRATO 2027'!M31:M37),0)
B30: Acabamentos (25 a 37) | D30: =SUM('RETRATO 2027'!F38:F50) | E30: =IF($D$32=0,0,D30/$D$32) | F30: =IFERROR(SUMPRODUCT('RETRATO 2027'!J38:J50,'RETRATO 2027'!M38:M50)/SUM('RETRATO 2027'!M38:M50),0)
B31: Taxa de administração | D31: =SUM('RETRATO 2027'!F52:F52) | E31: =IF($D$32=0,0,D31/$D$32)
B32: TOTAL | D32: =SUM(D26:D31) | E32: =SUM(E26:E31)
B33: Avanço financeiro = acumulado até dezembro do ano ÷ projeção. | F33: =IF(ABS(D32-F6)<1,"✓ confere com o cartão","⚠ diferente do cartão")
B36: CURVA S — % ACUMULADO DA PROJEÇÃO

Sheet Tabela
A1: ITEM | B1: Acu até Dez/24 | C1: 45658 | D1: 45689 | E1: 45717 | F1: 45748 | G1: 45778 | H1: 45809 | I1: 45839 | J1: 45870 | K1: 45901 | L1: 45931 | M1: 45962 | N1: TOTAL
A2: PROJETOS | B2: 936634 | C2: 104300 | D2: 109039 | E2: 96905 | F2: 52758 | G2: 118597 | H2: 174356 | I2: 81554 | J2: 117154 | K2: 51128 | L2: 22630 | M2: 85313 | N2: 1950368 | O2: 1950368
A3: SEGUROS | E3: 13813 | F3: 13812.5 | G3: 13812.5 | H3: 13812.5 | I3: 13812.5 | J3: 13812.5 | K3: 13812.5 | N3: 96688 | O3: 96688
A4: TAXAS DIVERSAS | B4: 1283 | C4: 543 | E4: 18 | F4: 927 | H4: 597 | I4: 927 | J4: 68 | K4: 70 | L4: 927 | N4: 5360 | O4: 5362
A5: BARRACAO DE OBRA | B5: 75504 | D5: 21458 | E5: 12780 | F5: 28138 | G5: 22900 | H5: 36417 | I5: 45821 | J5: 20358 | K5: 55545 | L5: 50343 | M5: 48899 | N5: 418163 | O5: 418163
A6: LIGAÇÕES PROVISÓRIAS ÁGUA, ENERGIA | F6: 5620 | G6: 2137 | I6: 1976 | J6: 5083 | K6: 1918 | M6: 2616 | N6: 19350 | O6: 19350
A7: CONSULTORIAS (OBRAS) | B7: 25881 | C7: 2679 | D7: 126910 | E7: 146680 | F7: 21272 | G7: 12379 | H7: 10621 | I7: 25742 | J7: 143973 | K7: 131293 | L7: 26251 | M7: 40013 | N7: 713694 | O7: 713695
A8: CONSUMO DE ÁGUA, ENERGIA, ETC. | B8: 2973 | C8: 880 | D8: 300 | E8: 96 | F8: 160 | G8: 160 | H8: 163 | I8: 1728 | J8: 3979 | K8: 5970 | L8: 5640 | M8: 10037 | N8: 32086 | O8: 32085
A9: TERRAPLENAGEM | B9: 59521 | C9: 1300 | G9: 58031 | H9: 244429 | I9: 369032 | J9: 540522 | K9: 262425 | L9: 144549 | M9: 234349 | N9: 1914158 | O9: 1914158
A10: CONTENÇÃO | B10: 41467 | D10: 34632 | E10: 70993 | F10: 294474 | G10: 451172 | H10: 303678 | I10: 216204 | J10: 539903 | K10: 234452 | L10: 410934 | M10: 83339 | N10: 2681248 | O10: 2681248
A11: FUNDAÇÃO PROFUNDA | B11: 232037 | E11: 1220 | F11: 17384 | G11: 291871 | H11: 265890 | I11: 772437 | J11: 672253 | K11: 1280306 | L11: 1153766 | M11: 515821 | N11: 5202985 | O11: 5202985
A12: FUNDAÇÃO SUPERFICIAL | B12: 37306 | H12: 1240 | I12: 94581 | J12: 105480 | K12: 159567 | L12: 265168 | M12: 794617 | N12: 1457959 | O12: 1457958
A13: EQUIPAMENTOS DE PROTEÇÃO COLETIVA | J13: 79 | K13: 79 | M13: 158 | N13: 316 | O13: 158
A14: ESTRUTURA EM CONCRETO ARMADO | B14: 136163 | E14: 3590 | G14: 220 | H14: 12968 | I14: 46305 | J14: 177220 | K14: 230173 | L14: 450721 | M14: 1318942 | N14: 2376302 | O14: 2376302
A15: INSTALAÇÕES ELÉTRICAS | B15: 870 | L15: 269924 | M15: 29963 | N15: 300757 | O15: 300775
A16: EQUIPAMENTOS E FERRAMENTAS | B16: 12559 | D16: 6150 | E16: 41488 | F16: 24534 | G16: 68934 | H16: 23694 | I16: 39162 | J16: 25432 | K16: 22326 | L16: 46948 | M16: 69797 | N16: 381024 | O16: 381022
A17: TRANSPORTES | B17: 15137 | C17: 4469 | D17: 1472 | E17: 72 | F17: 3294 | G17: 5791 | H17: 2577 | I17: 6010 | J17: 5623 | K17: 9962 | L17: 6569 | M17: 19254 | N17: 80230 | O17: 80230
A18: TAXA DE ADMINISTRAÇÃO | B18: 834265 | C18: 18060 | D18: 16699 | E18: 64178 | F18: 48428 | G18: 64629 | H18: 48665 | I18: 124956 | J18: 98792 | K18: 169239 | L18: 177088 | M18: 229852 | N18: 1894851 | O18: 1858731
A19: SERVIÇOS INICIAIS | B19: 4200 | C19: 29638 | D19: 12869 | E19: 797 | H19: 4350 | N19: 51854 | O19: 51854
A20: MÃO DE OBRA PRÓPRIA | B20: 89151 | C20: 10175 | D20: 44808 | E20: 70531 | F20: 163898 | G20: 192088 | H20: 260145 | I20: 275348 | J20: 267685 | K20: 267117 | L20: 373831 | M20: 351776 | N20: 2366553 | O20: 2366553
A21: DIVERSOS | B21: 6730 | C21: 532 | D21: 1150 | E21: 1077 | F21: 7674 | G21: 2821 | H21: 4689 | I21: 4207 | J21: 7357 | K21: 3942 | L21: 4591 | M21: 20147 | N21: 64917 | O21: 64917
A22: REEMBOLSO MATERIAIS E SERVIÇOS | B22: 30425 | C22: 38447 | D22: 24240 | E22: 633 | F22: 628 | G22: 2227 | H22: 3004 | I22: 4132 | J22: 3238 | K22: 4766 | N22: 111740 | O22: 111741
A23: SEGURANÇA DO TRABALHO | M23: 10781 | N23: 10781 | O23: 10781
A24: TOPOGRAFIA | J24: 9300 | K24: 9300 | N24: 18600 | O24: 18600
A25: CONDICIONANTES AMBIENTAIS | M25: 1863 | N25: 1863 | O25: 1863
A27: TOTAL | B27: 2542106 | C27: 211023 | D27: 399727 | E27: 524871 | F27: 683001.5 | G27: 1307769.5 | H27: 1411295.5 | I27: 2123934.5 | J27: 2757311.5 | K27: 2913390.5 | L27: 3409880 | M27: 3867537 | N27: 22151847 | O27: 22115587
M28: 22151847
A29: Total do BI | B29: 2542106 | C29: 174903 | D29: 399725 | E29: 524870 | F29: 683003 | G29: 1307768 | H29: 1411297 | I29: 2123934 | J29: 2757310 | K29: 2913390 | L29: 3409900 | M29: 3867378
M30: 22115584
C31: -36120 | M31: -36263 | O31: -36260

Sheet VALOR POR PL
B3: ORÇAMENTO SET/25 - BOTÂNICO | J3: ACOMPANHAMENTO IEC
B5: INCC 10-25 | C5: 1216.76 | D5: TOTAL | E5: =E50 | F5: =F50 | G5: =G50 | H5: INCC BASE DO ORÇAMENTO | J5: DATA DE CORTE -> | K5: 46235 | O5: Corte (1º dia do mês) | P5: =DATE(YEAR(K5),MONTH(K5),1)
B6: ORÇ EM INCC | C6: 143557.19 | H6: 1216.706 | J6: INÍCIO DO FLUXO -> | K6: 45627 | O6: Início (1º dia do mês) | P6: =DATE(YEAR(K6),MONTH(K6),1)
B7: ORÇ 10-25 | C7: =C6*C5 | D7: TAXA DE ADMINISTRAÇÃO | E7: =IF(F49=0,0,F48/F49) | F7: =F48 | G7: =G48 | J7: LIMITE DE AVANÇO FÍSICO P/ USAR PREVISION -> | K7: 1 | O7: INCC no mês de corte | P7: =IFERROR(INDEX('"INCC-FGV"'!$B$2:$B$800,MATCH(P5,'"INCC-FGV"'!$A$2:$A$800,0)),IFERROR(INDEX('"INCC-FGV"'!$B$2:$B$800,MATCH(P5,'"INCC-FGV"'!$A$2:$A$800,1)),"FALTA INCC"))
D8: SUBTOTAL | E8: =IF(F50=0,0,F49/F50) | F8: =F49 | G8: =G49 | J8: CENÁRIO DAS CURVAS -> | K8: PADRÃO | O8: Último mês do horizonte | P8: =DATE(YEAR(P6),MONTH(P6)+71,1)
O9: Obra | P9: BOTÂNICO
B10: CPU | C10: CÓDIGO | D10: DESCRIÇÃO / SERVIÇO | E10: PESO DO ORÇAMENTO | F10: VALOR EM R$ (orçamento base) | G10: VALOR EM INCC (orçamento) | H10: META EM INCC (soma da distribuição) | I10: TIPO | J10: PL | K10: ORÇAMENTO REAJUSTADO (INCC do corte) | L10: PROJEÇÃO (R$) | M10: VARIAÇÃO | N10: CONFERÊNCIA | O10: FONTE DA CURVA | P10: AVANÇO FÍSICO (Prevision, corte) | Q10: CÓD. NO PREVISION | R10: CURVA PREVISTA DE OUTRO PL (cód. Prevision) | S10: FATOR DA PROJEÇÃO (reorçamento)
B11: PL001.001 | C11: 01 | D11: PROJETOS | E11: =IF($F$50=0,0,F11/$F$50) | F11: 2400000 | G11: 1972.539 | H11: =MAX(G11*IF(S11="",1,S11),'PROJETO'!$K$8) | I11: INDIRETO | J11: PROJETOS | K11: =IF(ISNUMBER($P$7),G11*$P$7,0) | L11: ='PROJETO'!$J$7 | M11: =L11-K11 | N11: =IF(D11="","",IF('PROJETO'!$K$8>'PROJETO'!$K$6+0.01,"⚠ Incorrido acima da meta em INCC",IF(AND('PROJETO'!$K$18>1,'PROJETO'!$K$17=0),"⚠ Saldo sem curva (preencha a coluna H da aba)",IF(ABS('PROJETO'!$D$80)>0.01,"⚠ Verificar","OK")))) | O11: ='PROJETO'!$K$16 | P11: ='PROJETO'!$K$14 | Q11: 01 | S11: 1.0378621
B12: PL350.001 | C12: 02 | D12: SEGUROS | E12: =IF($F$50=0,0,F12/$F$50) | F12: 126154.98 | G12: 103.68567 | H12: =MAX(G12*IF(S12="",1,S12),'SEGUROS'!$K$8) | I12: INDIRETO | J12: SEGURO DE OBRA | K12: =IF(ISNUMBER($P$7),G12*$P$7,0) | L12: ='SEGUROS'!$J$7 | M12: =L12-K12 | N12: =IF(D12="","",IF('SEGUROS'!$K$8>'SEGUROS'!$K$6+0.01,"⚠ Incorrido acima da meta em INCC",IF(AND('SEGUROS'!$K$18>1,'SEGUROS'!$K$17=0),"⚠ Saldo sem curva (preencha a coluna H da aba)",IF(ABS('SEGUROS'!$D$80)>0.01,"⚠ Verificar","OK")))) | O12: ='SEGUROS'!$K$16 | P12: ='SEGUROS'!$K$14 | Q12: 02 | S12: 0.95674951
B13: PL001.016 | C13: 03 | D13: TAXAS DIVERSAS | E13: =IF($F$50=0,0,F13/$F$50) | F13: 150000 | G13: 123.28369 | H13: =MAX(G13*IF(S13="",1,S13),'TAX. DIVERSAS'!$K$8) | I13: INDIRETO | J13: TAXAS DIVERSAS | K13: =IF(ISNUMBER($P$7),G13*$P$7,0) | L13: ='TAX. DIVERSAS'!$J$7 | M13: =L13-K13 | N13: =IF(D13="","",IF('TAX. DIVERSAS'!$K$8>'TAX. DIVERSAS'!$K$6+0.01,"⚠ Incorrido acima da meta em INCC",IF(AND('TAX. DIVERSAS'!$K$18>1,'TAX. DIVERSAS'!$K$17=0),"⚠ Saldo sem curva (preencha a coluna H da aba)",IF(ABS('TAX. DIVERSAS'!$D$80)>0.01,"⚠ Verificar","OK")))) | O13: ='TAX. DIVERSAS'!$K$16 | P13: ='TAX. DIVERSAS'!$K$14 | Q13: 03
B14: PL010.005 | C14: 04 | D14: BARRACAO DE OBRA | E14: =IF($F$50=0,0,F14/$F$50) | F14: 934513.13 | G14: 768.06815 | H14: =MAX(G14*IF(S14="",1,S14),'BARRACÃO DE OBRA'!$K$8) | I14: INDIRETO | J14: BARRACAO DE OBRA | K14: =IF(ISNUMBER($P$7),G14*$P$7,0) | L14: ='BARRACÃO DE OBRA'!$J$7 | M14: =L14-K14 | N14: =IF(D14="","",IF('BARRACÃO DE OBRA'!$K$8>'BARRACÃO DE OBRA'!$K$6+0.01,"⚠ Incorrido acima da meta em INCC",IF(AND('BARRACÃO DE OBRA'!$K$18>1,'BARRACÃO DE OBRA'!$K$17=0),"⚠ Saldo sem curva (preencha a coluna H da aba)",IF(ABS('BARRACÃO DE OBRA'!$D$80)>0.01,"⚠ Verificar","OK")))) | O14: ='BARRACÃO DE OBRA'!$K$16 | P14: ='BARRACÃO DE OBRA'!$K$14 | Q14: 04 | S14: 1.2664432
B15: PL020.004 | C15: 05 | D15: LIGAÇÕES PROVISÓRIAS AGUA, ENERGIA,TELEFONIA, ESGOTO | E15: =IF($F$50=0,0,F15/$F$50) | F15: 50000 | G15: 41.094562 | H15: =MAX(G15*IF(S15="",1,S15),'LIG. PROVISÓRIAS'!$K$8) | I15: INDIRETO | J15: LIGAÇÕES PROVISÓRIAS AGUA, ESGOTO, ENERGIA,TELEFONE, INTERNET | K15: =IF(ISNUMBER($P$7),G15*$P$7,0) | L15: ='LIG. PROVISÓRIAS'!$J$7 | M15: =L15-K15 | N15: =IF(D15="","",IF('LIG. PROVISÓRIAS'!$K$8>'LIG. PROVISÓRIAS'!$K$6+0.01,"⚠ Incorrido acima da meta em INCC",IF(AND('LIG. PROVISÓRIAS'!$K$18>1,'LIG. PROVISÓRIAS'!$K$17=0),"⚠ Saldo sem curva (preencha a coluna H da aba)",IF(ABS('LIG. PROVISÓRIAS'!$D$80)>0.01,"⚠ Verificar","OK")))) | O15: ='LIG. PROVISÓRIAS'!$K$16 | P15: ='LIG. PROVISÓRIAS'!$K$14 | Q15: 05 | S15: 1.6884819
B16: PL020.005 | C16: 06 | D16: CONSUMO DE ÁGUA, ENERGIA, ETC. | E16: =IF($F$50=0,0,F16/$F$50) | F16: 521400 | G16: 428.53409 | H16: =MAX(G16*IF(S16="",1,S16),'CONSUMOS'!$K$8) | I16: INDIRETO | J16: CONSUMO DE ÁGUA, ENERGIA, TELEFONE, INTERNET | K16: =IF(ISNUMBER($P$7),G16*$P$7,0) | L16: ='CONSUMOS'!$J$7 | M16: =L16-K16 | N16: =IF(D16="","",IF('CONSUMOS'!$K$8>'CONSUMOS'!$K$6+0.01,"⚠ Incorrido acima da meta em INCC",IF(AND('CONSUMOS'!$K$18>1,'CONSUMOS'!$K$17=0),"⚠ Saldo sem curva (preencha a coluna H da aba)",IF(ABS('CONSUMOS'!$D$80)>0.01,"⚠ Verificar","OK")))) | O16: ='CONSUMOS'!$K$16 | P16: ='CONSUMOS'!$K$14 | Q16: 06 | S16: 1.044686
B17: PL310.007 | C17: 07 | D17: DIVERSOS | E17: =IF($F$50=0,0,F17/$F$50) | F17: 158400 | G17: 130.18757 | H17: =MAX(G17*IF(S17="",1,S17),'DIVERSOS'!$K$8) | I17: INDIRETO | J17: DIVERSOS | K17: =IF(ISNUMBER($P$7),G17*$P$7,0) | L17: ='DIVERSOS'!$J$7 | M17: =L17-K17 | N17: =IF(D17="","",IF('DIVERSOS'!$K$8>'DIVERSOS'!$K$6+0.01,"⚠ Incorrido acima da meta em INCC",IF(AND('DIVERSOS'!$K$18>1,'DIVERSOS'!$K$17=0),"⚠ Saldo sem curva (preencha a coluna H da aba)",IF(ABS('DIVERSOS'!$D$80)>0.01,"⚠ Verificar","OK")))) | O17: ='DIVERSOS'!$K$16 | P17: ='DIVERSOS'!$K$14 | Q17: 07 | S17: 1.171028
B18: PL570.001 | C18: 08 | D18: TRANSPORTES | E18: =IF($F$50=0,0,F18/$F$50) | F18: 779592 | G18: 640.73983 | H18: =MAX(G18*IF(S18="",1,S18),'TRANSPORTES'!$K$8) | I18: INDIRETO | J18: FRETES E TRANSPORTES | K18: =IF(ISNUMBER($P$7),G18*$P$7,0) | L18: ='TRANSPORTES'!$J$7 | M18: =L18-K18 | N18: =IF(D18="","",IF('TRANSPORTES'!$K$8>'TRANSPORTES'!$K$6+0.01,"⚠ Incorrido acima da meta em INCC",IF(AND('TRANSPORTES'!$K$18>1,'TRANSPORTES'!$K$17=0),"⚠ Saldo sem curva (preencha a coluna H da aba)",IF(ABS('TRANSPORTES'!$D$80)>0.01,"⚠ Verificar","OK")))) | O18: ='TRANSPORTES'!$K$16 | P18: ='TRANSPORTES'!$K$14 | Q18: 08 | S18: 1.0092106
B19: PL001.051 | C19: 09 | D19: CONSULTORIAS (OBRAS) | E19: =IF($F$50=0,0,F19/$F$50) | F19: 1322661 | G19: 1087.0835 | H19: =MAX(G19*IF(S19="",1,S19),'CONSULTORIAS'!$K$8) | I19: INDIRETO | J19: CONSULTORIAS (OBRAS) | K19: =IF(ISNUMBER($P$7),G19*$P$7,0) | L19: ='CONSULTORIAS'!$J$7 | M19: =L19-K19 | N19: =IF(D19="","",IF('CONSULTORIAS'!$K$8>'CONSULTORIAS'!$K$6+0.01,"⚠ Incorrido acima da meta em INCC",IF(AND('CONSULTORIAS'!$K$18>1,'CONSULTORIAS'!$K$17=0),"⚠ Saldo sem curva (preencha a coluna H da aba)",IF(ABS('CONSULTORIAS'!$D$80)>0.01,"⚠ Verificar","OK")))) | O19: ='CONSULTORIAS'!$K$16 | P19: ='CONSULTORIAS'!$K$14 | Q19: 09 | S19: 0.98533299
B20: PL700.001 | C20: 10 | D20: MÃO DE OBRA PRÓPRIA | E20: =IF($F$50=0,0,F20/$F$50) | F20: 20188025 | G20: 16592.36 | H20: =MAX(G20*IF(S20="",1,S20),'MDO'!$K$8) | I20: INDIRETO | J20: MÃO DE OBRA PRÓPRIA | K20: =IF(ISNUMBER($P$7),G20*$P$7,0) | L20: ='MDO'!$J$7 | M20: =L20-K20 | N20: =IF(D20="","",IF('MDO'!$K$8>'MDO'!$K$6+0.01,"⚠ Incorrido acima da meta em INCC",IF(AND('MDO'!$K$18>1,'MDO'!$K$17=0),"⚠ Saldo sem curva (preencha a coluna H da aba)",IF(ABS('MDO'!$D$80)>0.01,"⚠ Verificar","OK")))) | O20: ='MDO'!$K$16 | P20: ='MDO'!$K$14 | Q20: 10
B21: PL530.001 | C21: 11 | D21: EQUIPAMENTOS E FERRAMENTAS | E21: =IF($F$50=0,0,F21/$F$50) | F21: 6467911.7 | G21: 5315.9199 | H21: =MAX(G21*IF(S21="",1,S21),'EQUIP E FER'!$K$8) | I21: INDIRETO | J21: EQUIPAMENTOS E FERRAMENTAS | K21: =IF(ISNUMBER($P$7),G21*$P$7,0) | L21: ='EQUIP E FER'!$J$7 | M21: =L21-K21 | N21: =IF(D21="","",IF('EQUIP E FER'!$K$8>'EQUIP E FER'!$K$6+0.01,"⚠ Incorrido acima da meta em INCC",IF(AND('EQUIP E FER'!$K$18>1,'EQUIP E FER'!$K$17=0),"⚠ Saldo sem curva (preencha a coluna H da aba)",IF(ABS('EQUIP E FER'!$D$80)>0.01,"⚠ Verificar","OK")))) | O21: ='EQUIP E FER'!$K$16 | P21: ='EQUIP E FER'!$K$14 | Q21: 11 | S21: 0.99703491
B22: PL010.022 | C22: 12 | D22: SERVIÇOS INICIAIS | E22: =IF($F$50=0,0,F22/$F$50) | F22: 175350.93 | G22: 144.11939 | H22: =MAX(G22*IF(S22="",1,S22),'SERV. INICIAIS'!$K$8) | I22: DIRETO | J22: SERVIÇOS INICIAIS | K22: =IF(ISNUMBER($P$7),G22*$P$7,0) | L22: ='SERV. INICIAIS'!$J$7 | M22: =L22-K22 | N22: =IF(D22="","",IF('SERV. INICIAIS'!$K$8>'SERV. INICIAIS'!$K$6+0.01,"⚠ Incorrido acima da meta em INCC",IF(AND('SERV. INICIAIS'!$K$18>1,'SERV. INICIAIS'!$K$17=0),"⚠ Saldo sem curva (preencha a coluna H da aba)",IF(ABS('SERV. INICIAIS'!$D$80)>0.01,"⚠ Verificar","OK")))) | O22: ='SERV. INICIAIS'!$K$16 | P22: ='SERV. INICIAIS'!$K$14 | Q22: 12 | S22: 0.94870607
B23: PL001.023 | C23: 13 | D23: CONTENÇÃO | E23: =IF($F$50=0,0,F23/$F$50) | F23: 1644553.5 | G23: 1351.6441 | H23: =MAX(G23*IF(S23="",1,S23),'CONTENÇÃO'!$K$8) | I23: DIRETO | J23: CONTENÇÕES | K23: =IF(ISNUMBER($P$7),G23*$P$7,0) | L23: ='CONTENÇÃO'!$J$7 | M23: =L23-K23 | N23: =IF(D23="","",IF('CONTENÇÃO'!$K$8>'CONTENÇÃO'!$K$6+0.01,"⚠ Incorrido acima da meta em INCC",IF(AND('CONTENÇÃO'!$K$18>1,'CONTENÇÃO'!$K$17=0),"⚠ Saldo sem curva (preencha a coluna H da aba)",IF(ABS('CONTENÇÃO'!$D$80)>0.01,"⚠ Verificar","OK")))) | O23: ='CONTENÇÃO'!$K$16 | P23: ='CONTENÇÃO'!$K$14 | Q23: 13 | S23: 0.84684312
B24: PL040.001 | C24: 14 | D24: TERRAPLENAGEM | E24: =IF($F$50=0,0,F24/$F$50) | F24: 1259784.5 | G24: 1035.4058 | H24: =MAX(G24*IF(S24="",1,S24),'TERRAPLENAGEM'!$K$8) | I24: DIRETO | J24: TERRAPLENAGEM | K24: =IF(ISNUMBER($P$7),G24*$P$7,0) | L24: ='TERRAPLENAGEM'!$J$7 | M24: =L24-K24 | N24: =IF(D24="","",IF('TERRAPLENAGEM'!$K$8>'TERRAPLENAGEM'!$K$6+0.01,"⚠ Incorrido acima da meta em INCC",IF(AND('TERRAPLENAGEM'!$K$18>1,'TERRAPLENAGEM'!$K$17=0),"⚠ Saldo sem curva (preencha a coluna H da aba)",IF(ABS('TERRAPLENAGEM'!$D$80)>0.01,"⚠ Verificar","OK")))) | O24: ='TERRAPLENAGEM'!$K$16 | P24: ='TERRAPLENAGEM'!$K$14 | Q24: 14 | S24: 0.96743828
B25: PL050.004 | C25: 15 | D25: FUNDAÇÃO PROFUNDA | E25: =IF($F$50=0,0,F25/$F$50) | F25: 6226579.2 | G25: 5117.5709 | H25: =MAX(G25*IF(S25="",1,S25),'FUND. PROF'!$K$8) | I25: DIRETO | J25: FUNDAÇÃO PROFUNDA | K25: =IF(ISNUMBER($P$7),G25*$P$7,0) | L25: ='FUND. PROF'!$J$7 | M25: =L25-K25 | N25: =IF(D25="","",IF('FUND. PROF'!$K$8>'FUND. PROF'!$K$6+0.01,"⚠ Incorrido acima da meta em INCC",IF(AND('FUND. PROF'!$K$18>1,'FUND. PROF'!$K$17=0),"⚠ Saldo sem curva (preencha a coluna H da aba)",IF(ABS('FUND. PROF'!$D$80)>0.01,"⚠ Verificar","OK")))) | O25: ='FUND. PROF'!$K$16 | P25: ='FUND. PROF'!$K$14 | Q25: 15 | S25: 1.0625743
B26: PL060.004 | C26: 16 | D26: FUNDAÇÃO SUPERFICIAL | E26: =IF($F$50=0,0,F26/$F$50) | F26: 4057797.9 | G26: 3335.0685 | H26: =MAX(G26*IF(S26="",1,S26),'FUND. SUP'!$K$8) | I26: DIRETO | J26: FUNDAÇÃO SUPERFICIAL | K26: =IF(ISNUMBER($P$7),G26*$P$7,0) | L26: ='FUND. SUP'!$J$7 | M26: =L26-K26 | N26: =IF(D26="","",IF('FUND. SUP'!$K$8>'FUND. SUP'!$K$6+0.01,"⚠ Incorrido acima da meta em INCC",IF(AND('FUND. SUP'!$K$18>1,'FUND. SUP'!$K$17=0),"⚠ Saldo sem curva (preencha a coluna H da aba)",IF(ABS('FUND. SUP'!$D$80)>0.01,"⚠ Verificar","OK")))) | O26: ='FUND. SUP'!$K$16 | P26: ='FUND. SUP'!$K$14 | Q26: 16 | S26: 1.0107429
B27: PL100.011 | C27: 17 | D27: ESTRUTURA EM CONCRETO ARMADO | E27: =IF($F$50=0,0,F27/$F$50) | F27: 25651082 | G27: 21082.399 | H27: =MAX(G27*IF(S27="",1,S27),'ESTRUTURA'!$K$8) | I27: DIRETO | J27: ESTRUTURA EM CONCRETO ARMADO | K27: =IF(ISNUMBER($P$7),G27*$P$7,0) | L27: ='ESTRUTURA'!$J$7 | M27: =L27-K27 | N27: =IF(D27="","",IF('ESTRUTURA'!$K$8>'ESTRUTURA'!$K$6+0.01,"⚠ Incorrido acima da meta em INCC",IF(AND('ESTRUTURA'!$K$18>1,'ESTRUTURA'!$K$17=0),"⚠ Saldo sem curva (preencha a coluna H da aba)",IF(ABS('ESTRUTURA'!$D$80)>0.01,"⚠ Verificar","OK")))) | O27: ='ESTRUTURA'!$K$16 | P27: ='ESTRUTURA'!$K$14 | Q27: 17 | S27: 0.99428727
B28: PL120.001 | C28: 18 | D28: ALVENARIA | E28: =IF($F$50=0,0,F28/$F$50) | F28: 5927475.7 | G28: 4871.7403 | H28: =MAX(G28*IF(S28="",1,S28),'ALVENARIA'!$K$8) | I28: DIRETO | J28: ALVENARIA | K28: =IF(ISNUMBER($P$7),G28*$P$7,0) | L28: ='ALVENARIA'!$J$7 | M28: =L28-K28 | N28: =IF(D28="","",IF('ALVENARIA'!$K$8>'ALVENARIA'!$K$6+0.01,"⚠ Incorrido acima da meta em INCC",IF(AND('ALVENARIA'!$K$18>1,'ALVENARIA'!$K$17=0),"⚠ Saldo sem curva (preencha a coluna H da aba)",IF(ABS('ALVENARIA'!$D$80)>0.01,"⚠ Verificar","OK")))) | O28: ='ALVENARIA'!$K$16 | P28: ='ALVENARIA'!$K$14 | Q28: 18
B29: PL140.004 | C29: 19 | D29: IMPERMEABILIZAÇÃO | E29: =IF($F$50=0,0,F29/$F$50) | F29: 3928343.3 | G29: 3228.6709 | H29: =MAX(G29*IF(S29="",1,S29),'IMPERMEABILIZAÇÃO'!$K$8) | I29: DIRETO | J29: IMPERMEABILIZAÇÃO | K29: =IF(ISNUMBER($P$7),G29*$P$7,0) | L29: ='IMPERMEABILIZAÇÃO'!$J$7 | M29: =L29-K29 | N29: =IF(D29="","",IF('IMPERMEABILIZAÇÃO'!$K$8>'IMPERMEABILIZAÇÃO'!$K$6+0.01,"⚠ Incorrido acima da meta em INCC",IF(AND('IMPERMEABILIZAÇÃO'!$K$18>1,'IMPERMEABILIZAÇÃO'!$K$17=0),"⚠ Saldo sem curva (preencha a coluna H da aba)",IF(ABS('IMPERMEABILIZAÇÃO'!$D$80)>0.01,"⚠ Verificar","OK")))) | O29: ='IMPERMEABILIZAÇÃO'!$K$16 | P29: ='IMPERMEABILIZAÇÃO'!$K$14 | Q29: 19
B30: PL110.018 | C30: 20 | D30: INSTALAÇÕES ELÉTRICAS | E30: =IF($F$50=0,0,F30/$F$50) | F30: 11262627 | G30: 9256.6542 | H30: =MAX(G30*IF(S30="",1,S30),'INST. ELÉTRICA'!$K$8) | I30: DIRETO | J30: INSTALAÇÕES ELÉTRICAS | K30: =IF(ISNUMBER($P$7),G30*$P$7,0) | L30: ='INST. ELÉTRICA'!$J$7 | M30: =L30-K30 | N30: =IF(D30="","",IF('INST. ELÉTRICA'!$K$8>'INST. ELÉTRICA'!$K$6+0.01,"⚠ Incorrido acima da meta em INCC",IF(AND('INST. ELÉTRICA'!$K$18>1,'INST. ELÉTRICA'!$K$17=0),"⚠ Saldo sem curva (preencha a coluna H da aba)",IF(ABS('INST. ELÉTRICA'!$D$80)>0.01,"⚠ Verificar","OK")))) | O30: ='INST. ELÉTRICA'!$K$16 | P30: ='INST. ELÉTRICA'!$K$14 | Q30: 20 | S30: 0.97146252
B31: PL110.007 | C31: 21 | D31: INSTALAÇÕES HIDROSANITÁRIAS | E31: =IF($F$50=0,0,F31/$F$50) | F31: 7374040 | G31: 6060.6589 | H31: =MAX(G31*IF(S31="",1,S31),'INST. HIDRO'!$K$8) | I31: DIRETO | J31: INSTALAÇÕES HIDROSANITÁRIAS | K31: =IF(ISNUMBER($P$7),G31*$P$7,0) | L31: ='INST. HIDRO'!$J$7 | M31: =L31-K31 | N31: =IF(D31="","",IF('INST. HIDRO'!$K$8>'INST. HIDRO'!$K$6+0.01,"⚠ Incorrido acima da meta em INCC",IF(AND('INST. HIDRO'!$K$18>1,'INST. HIDRO'!$K$17=0),"⚠ Saldo sem curva (preencha a coluna H da aba)",IF(ABS('INST. HIDRO'!$D$80)>0.01,"⚠ Verificar","OK")))) | O31: ='INST. HIDRO'!$K$16 | P31: ='INST. HIDRO'!$K$14 | Q31: 21
B32: PL110.017 | C32: 22 | D32: INSTALAÇÕES COMBATE INCÊNDIO | E32: =IF($F$50=0,0,F32/$F$50) | F32: 781560 | G32: 642.35732 | H32: =MAX(G32*IF(S32="",1,S32),'INST. INC'!$K$8) | I32: DIRETO | J32: INSTALAÇÕES COMBATE INCÊNDIO | K32: =IF(ISNUMBER($P$7),G32*$P$7,0) | L32: ='INST. INC'!$J$7 | M32: =L32-K32 | N32: =IF(D32="","",IF('INST. INC'!$K$8>'INST. INC'!$K$6+0.01,"⚠ Incorrido acima da meta em INCC",IF(AND('INST. INC'!$K$18>1,'INST. INC'!$K$17=0),"⚠ Saldo sem curva (preencha a coluna H da aba)",IF(ABS('INST. INC'!$D$80)>0.01,"⚠ Verificar","OK")))) | O32: ='INST. INC'!$K$16 | P32: ='INST. INC'!$K$14 | Q32: 22
B33: PL110.027 | C33: 23 | D33: INSTALAÇÕES ESPECIAIS | E33: =IF($F$50=0,0,F33/$F$50) | F33: 2684762.9 | G33: 2206.5831 | H33: =MAX(G33*IF(S33="",1,S33),'INST. ESP'!$K$8) | I33: DIRETO | J33: INSTALAÇÕES ESPECIAIS | K33: =IF(ISNUMBER($P$7),G33*$P$7,0) | L33: ='INST. ESP'!$J$7 | M33: =L33-K33 | N33: =IF(D33="","",IF('INST. ESP'!$K$8>'INST. ESP'!$K$6+0.01,"⚠ Incorrido acima da meta em INCC",IF(AND('INST. ESP'!$K$18>1,'INST. ESP'!$K$17=0),"⚠ Saldo sem curva (preencha a coluna H da aba)",IF(ABS('INST. ESP'!$D$80)>0.01,"⚠ Verificar","OK")))) | O33: ='INST. ESP'!$K$16 | P33: ='INST. ESP'!$K$14 | Q33: 23
B34: PL220.002 | C34: 24 | D34: ELEVADORES | E34: =IF($F$50=0,0,F34/$F$50) | F34: 3236182.1 | G34: 2659.7897 | H34: =MAX(G34*IF(S34="",1,S34),'ELEVADORES '!$K$8) | I34: DIRETO | J34: ELEVADORES | K34: =IF(ISNUMBER($P$7),G34*$P$7,0) | L34: ='ELEVADORES '!$J$7 | M34: =L34-K34 | N34: =IF(D34="","",IF('ELEVADORES '!$K$8>'ELEVADORES '!$K$6+0.01,"⚠ Incorrido acima da meta em INCC",IF(AND('ELEVADORES '!$K$18>1,'ELEVADORES '!$K$17=0),"⚠ Saldo sem curva (preencha a coluna H da aba)",IF(ABS('ELEVADORES '!$D$80)>0.01,"⚠ Verificar","OK")))) | O34: ='ELEVADORES '!$K$16 | P34: ='ELEVADORES '!$K$14 | Q34: 24
B35: PL250.001 | C35: 25 | D35: ESQUADRIAS | E35: =IF($F$50=0,0,F35/$F$50) | F35: 11181480 | G35: 9189.9602 | H35: =MAX(G35*IF(S35="",1,S35),'ESQUADRIAS'!$K$8) | I35: DIRETO | J35: ESQUADRIAS | K35: =IF(ISNUMBER($P$7),G35*$P$7,0) | L35: ='ESQUADRIAS'!$J$7 | M35: =L35-K35 | N35: =IF(D35="","",IF('ESQUADRIAS'!$K$8>'ESQUADRIAS'!$K$6+0.01,"⚠ Incorrido acima da meta em INCC",IF(AND('ESQUADRIAS'!$K$18>1,'ESQUADRIAS'!$K$17=0),"⚠ Saldo sem curva (preencha a coluna H da aba)",IF(ABS('ESQUADRIAS'!$D$80)>0.01,"⚠ Verificar","OK")))) | O35: ='ESQUADRIAS'!$K$16 | P35: ='ESQUADRIAS'!$K$14 | Q35: 25
B36: PL240.000 | C36: 26 | D36: SERRALHERIA | E36: =IF($F$50=0,0,F36/$F$50) | F36: 482766.76 | G36: 396.78177 | H36: =MAX(G36*IF(S36="",1,S36),'SERRALHERIA'!$K$8) | I36: DIRETO | J36: SERRALHERIA | K36: =IF(ISNUMBER($P$7),G36*$P$7,0) | L36: ='SERRALHERIA'!$J$7 | M36: =L36-K36 | N36: =IF(D36="","",IF('SERRALHERIA'!$K$8>'SERRALHERIA'!$K$6+0.01,"⚠ Incorrido acima da meta em INCC",IF(AND('SERRALHERIA'!$K$18>1,'SERRALHERIA'!$K$17=0),"⚠ Saldo sem curva (preencha a coluna H da aba)",IF(ABS('SERRALHERIA'!$D$80)>0.01,"⚠ Verificar","OK")))) | O36: ='SERRALHERIA'!$K$16 | P36: ='SERRALHERIA'!$K$14 | Q36: 26
B37: PL240.020 | C37: 27 | D37: MARCENARIA | E37: =IF($F$50=0,0,F37/$F$50) | F37: 2977368.4 | G37: 2447.073 | H37: =MAX(G37*IF(S37="",1,S37),'MARCENARIA'!$K$8) | I37: DIRETO | J37: MARCENARIA | K37: =IF(ISNUMBER($P$7),G37*$P$7,0) | L37: ='MARCENARIA'!$J$7 | M37: =L37-K37 | N37: =IF(D37="","",IF('MARCENARIA'!$K$8>'MARCENARIA'!$K$6+0.01,"⚠ Incorrido acima da meta em INCC",IF(AND('MARCENARIA'!$K$18>1,'MARCENARIA'!$K$17=0),"⚠ Saldo sem curva (preencha a coluna H da aba)",IF(ABS('MARCENARIA'!$D$80)>0.01,"⚠ Verificar","OK")))) | O37: ='MARCENARIA'!$K$16 | P37: ='MARCENARIA'!$K$14 | Q37: 27
B38: PL160.001 | C38: 28 | D38: REVESTIMENTOS DE MASSA EM PISOS | E38: =IF($F$50=0,0,F38/$F$50) | F38: 1096073.3 | G38: 900.85307 | H38: =MAX(G38*IF(S38="",1,S38),'REV. PISOS'!$K$8) | I38: DIRETO | J38: REVESTIMENTOS DE MASSA EM PISOS | K38: =IF(ISNUMBER($P$7),G38*$P$7,0) | L38: ='REV. PISOS'!$J$7 | M38: =L38-K38 | N38: =IF(D38="","",IF('REV. PISOS'!$K$8>'REV. PISOS'!$K$6+0.01,"⚠ Incorrido acima da meta em INCC",IF(AND('REV. PISOS'!$K$18>1,'REV. PISOS'!$K$17=0),"⚠ Saldo sem curva (preencha a coluna H da aba)",IF(ABS('REV. PISOS'!$D$80)>0.01,"⚠ Verificar","OK")))) | O38: ='REV. PISOS'!$K$16 | P38: ='REV. PISOS'!$K$14 | Q38: 28
B39: PL150.001 | C39: 29 | D39: REVESTIMENTOS DE MASSA EM PAREDES | E39: =IF($F$50=0,0,F39/$F$50) | F39: 2518191.2 | G39: 2069.6793 | H39: =MAX(G39*IF(S39="",1,S39),'REV. PAREDE'!$K$8) | I39: DIRETO | J39: REVESTIMENTOS DE MASSA EM PAREDES | K39: =IF(ISNUMBER($P$7),G39*$P$7,0) | L39: ='REV. PAREDE'!$J$7 | M39: =L39-K39 | N39: =IF(D39="","",IF('REV. PAREDE'!$K$8>'REV. PAREDE'!$K$6+0.01,"⚠ Incorrido acima da meta em INCC",IF(AND('REV. PAREDE'!$K$18>1,'REV. PAREDE'!$K$17=0),"⚠ Saldo sem curva (preencha a coluna H da aba)",IF(ABS('REV. PAREDE'!$D$80)>0.01,"⚠ Verificar","OK")))) | O39: ='REV. PAREDE'!$K$16 | P39: ='REV. PAREDE'!$K$14 | Q39: 29
B40: PL170.004 | C40: 30 | D40: REVESTIMENTOS DE ACABAMENTO | E40: =IF($F$50=0,0,F40/$F$50) | F40: 10402356 | G40: 8549.6054 | H40: =MAX(G40*IF(S40="",1,S40),'REV. ACAB'!$K$8) | I40: DIRETO | J40: REVESTIMENTOS DE ACABAMENTO | K40: =IF(ISNUMBER($P$7),G40*$P$7,0) | L40: ='REV. ACAB'!$J$7 | M40: =L40-K40 | N40: =IF(D40="","",IF('REV. ACAB'!$K$8>'REV. ACAB'!$K$6+0.01,"⚠ Incorrido acima da meta em INCC",IF(AND('REV. ACAB'!$K$18>1,'REV. ACAB'!$K$17=0),"⚠ Saldo sem curva (preencha a coluna H da aba)",IF(ABS('REV. ACAB'!$D$80)>0.01,"⚠ Verificar","OK")))) | O40: ='REV. ACAB'!$K$16 | P40: ='REV. ACAB'!$K$14 | Q40: 30
B41: PL320.001 | C41: 31 | D41: PAVIMENTAÇÃO | E41: =IF($F$50=0,0,F41/$F$50) | F41: 106895.67 | G41: 87.856614 | H41: =MAX(G41*IF(S41="",1,S41),'PAVIMENTAÇÃO'!$K$8) | I41: DIRETO | J41: PAVIMENTÇÃO | K41: =IF(ISNUMBER($P$7),G41*$P$7,0) | L41: ='PAVIMENTAÇÃO'!$J$7 | M41: =L41-K41 | N41: =IF(D41="","",IF('PAVIMENTAÇÃO'!$K$8>'PAVIMENTAÇÃO'!$K$6+0.01,"⚠ Incorrido acima da meta em INCC",IF(AND('PAVIMENTAÇÃO'!$K$18>1,'PAVIMENTAÇÃO'!$K$17=0),"⚠ Saldo sem curva (preencha a coluna H da aba)",IF(ABS('PAVIMENTAÇÃO'!$D$80)>0.01,"⚠ Verificar","OK")))) | O41: ='PAVIMENTAÇÃO'!$K$16 | P41: ='PAVIMENTAÇÃO'!$K$14 | Q41: 31
B42: PL190.003 | C42: 32 | D42: REVESTIMENTO DIVERSOS - FACHADA | E42: =IF($F$50=0,0,F42/$F$50) | F42: 5055622.3 | G42: 4155.1717 | H42: =MAX(G42*IF(S42="",1,S42),'REV. FACHADA'!$K$8) | I42: DIRETO | J42: REVESTIMENTO DIVERSOS - FACHADA | K42: =IF(ISNUMBER($P$7),G42*$P$7,0) | L42: ='REV. FACHADA'!$J$7 | M42: =L42-K42 | N42: =IF(D42="","",IF('REV. FACHADA'!$K$8>'REV. FACHADA'!$K$6+0.01,"⚠ Incorrido acima da meta em INCC",IF(AND('REV. FACHADA'!$K$18>1,'REV. FACHADA'!$K$17=0),"⚠ Saldo sem curva (preencha a coluna H da aba)",IF(ABS('REV. FACHADA'!$D$80)>0.01,"⚠ Verificar","OK")))) | O42: ='REV. FACHADA'!$K$16 | P42: ='REV. FACHADA'!$K$14 | Q42: 32
B43: PL180.001 | C43: 33 | D43: FORRO | E43: =IF($F$50=0,0,F43/$F$50) | F43: 1690544.9 | G43: 1389.444 | H43: =MAX(G43*IF(S43="",1,S43),'FORRO'!$K$8) | I43: DIRETO | J43: FORROS DIVERSOS | K43: =IF(ISNUMBER($P$7),G43*$P$7,0) | L43: ='FORRO'!$J$7 | M43: =L43-K43 | N43: =IF(D43="","",IF('FORRO'!$K$8>'FORRO'!$K$6+0.01,"⚠ Incorrido acima da meta em INCC",IF(AND('FORRO'!$K$18>1,'FORRO'!$K$17=0),"⚠ Saldo sem curva (preencha a coluna H da aba)",IF(ABS('FORRO'!$D$80)>0.01,"⚠ Verificar","OK")))) | O43: ='FORRO'!$K$16 | P43: ='FORRO'!$K$14 | Q43: 33
...

Sheet RETRATO 2027
B2: ='VALOR POR PL'!$P$9&" · RETRATO DE "&D5
B3: ="Execução física (Prevision), desembolso do ano (fluxo financeiro) e situação da obra em 31/12/"&D5&" · Corte: "&CHOOSE(MONTH('VALOR POR PL'!$P$5),"jan","fev","mar","abr","mai","jun","jul","ago","set","out","nov","dez")&"/"&YEAR('VALOR POR PL'!$P$5)&" · Cenário: "&IF('VALOR POR PL'!$K$8="PADRÃO","padrão","Prevision")
B5: ANO DO RETRATO → | D5: 2027 | E5: INCC → | F5: ='VALOR POR PL'!$P$5 | G5: =IFERROR(INDEX('"INCC-FGV"'!$B$2:$B$800,MATCH(DATE(YEAR(F5),MONTH(F5),1),'"INCC-FGV"'!$A$2:$A$800,0)),IFERROR(INDEX('"INCC-FGV"'!$B$2:$B$800,MATCH(DATE(YEAR(F5),MONTH(F5),1),'"INCC-FGV"'!$A$2:$A$800,1)),"FALTA INCC")) | J5: SITUAÇÃO EM → | K5: =DATE(D5,12,31)
B7: DESEMBOLSO NO ANO (R$ NOMINAL) | D7: DESEMBOLSO NO ANO (INCC) | F7: EM R$ DO INCC SELECIONADO | H7: EXECUÇÃO FÍSICA NO FIM DO ANO | J7: AVANÇO FINANCEIRO | K7: MAIOR DESEMBOLSO DO ANO
B8: =F53 | D8: =G53 | F8: =H53 | H8: =IFERROR(SUMPRODUCT(D12:D50,N12:N50)/SUMPRODUCT(ISNUMBER(D12:D50)*N12:N50),0) | J8: =IFERROR(SUMPRODUCT(J12:J50,M12:M50)/SUM(M12:M50),0) | K8: {=INDEX(C12:C50,MATCH(MAX(IF(LEN(B12:B50)=2,F12:F50)),IF(LEN(B12:B50)=2,F12:F50),0))}
B9: com taxa de administração | D9: pontos de índice | F9: INCC × índice do mês escolhido | H9: itens diretos, ponderado pela projeção | J9: acumulado no fim do ano | K9: {="R$ "&TEXT(MAX(IF(LEN(B12:B50)=2,F12:F50))/1000000,"0.0")&" mi no ano"}
B11: Cód. | C11: PL / serviço | D11: Execução física fim do ano (Prevision) | E11: Execução física no corte (Prevision) | F11: Desembolso no ano R$ nominal | G11: Desembolso no ano INCC | H11: Desembolso no ano R$ do INCC selecionado | I11: % do ano | J11: Avanço financeiro fim do ano | K11: ="Situação em 31/12/"&D5&" (cronograma de atividades do Prevision)" | L11: Anotação do modelo anterior / justificativa
B12: ='VALOR POR PL'!C11 | C12: ='VALOR POR PL'!D11 | D12: =IF(OR('VALOR POR PL'!I11<>"DIRETO",'CP RESUMO'!$C$5=""),"",IFERROR(INDEX('CP RESUMO'!$D$5:$BW$5,MATCH(DATE($D$5,12,1),'CP RESUMO'!$D$4:$BW$4,0))/100,"")) | E12: =IF('VALOR POR PL'!I11<>"DIRETO","",'PROJETO'!$K$14) | F12: =SUMPRODUCT((YEAR('PROJETO'!$B$5:$B$76)=$D$5)*('PROJETO'!$C$5:$C$76+'PROJETO'!$D$5:$D$76)) | G12: =SUMPRODUCT((YEAR('MODELO PARA BI'!$H$1:$CA$1)=$D$5)*'MODELO PARA BI'!$H$29:$CA$29) | H12: =IF(ISNUMBER($G$5),G12*$G$5,0) | I12: =IF($F$53=0,0,F12/$F$53) | J12: =IF('VALOR POR PL'!L11=0,0,SUMPRODUCT(('PROJETO'!$B$5:$B$76<=DATE($D$5,12,1))*('PROJETO'!$C$5:$C$76+'PROJETO'!$D$5:$D$76))/'VALOR POR PL'!L11) | K12: {=IF(COUNTIF('CRONOGRAMA ATIVIDADES'!$M$5:$M$6004,B12)=0,"",IF(COUNTIFS('CRONOGRAMA ATIVIDADES'!$M$5:$M$6004,B12,'CRONOGRAMA ATIVIDADES'!$O$5:$O$6004,"CONCLUÍDA")=COUNTIF('CRONOGRAMA ATIVIDADES'!$M$5:$M$6004,B12),"Concluído (todas as "&COUNTIF('CRONOGRAMA ATIVIDADES'!$M$5:$M$6004,B12)&" atividades)",IF(COUNTIFS('CRONOGRAMA ATIVIDADES'!$M$5:$M$6004,B12,'CRONOGRAMA ATIVIDADES'!$O$5:$O$6004,"A INICIAR")=COUNTIF('CRONOGRAMA ATIVIDADES'!$M$5:$M$6004,B12),"Não iniciado · início previsto em "&CHOOSE(MONTH(_xlfn.MINIFS('CRONOGRAMA ATIVIDADES'!$F$5:$F$6004,'CRONOGRAMA ATIVIDADES'!$M$5:$M$6004,B12)),"jan","fev","mar","abr","mai","jun","jul","ago","set","out","nov","dez")&"/"&YEAR(_xlfn.MINIFS('CRONOGRAMA ATIVIDADES'!$F$5:$F$6004,'CRONOGRAMA ATIVIDADES'!$M$5:$M$6004,B12)),_xlfn.TEXTJOIN(" / ",TRUE,IF(('CRONOGRAMA ATIVIDADES'!$S$5:$S$304=B12)*('CRONOGRAMA ATIVIDADES'!$AA$5:$AA$304<>""),'CRONOGRAMA ATIVIDADES'!$AA$5:$AA$304,"")))))} | M12: ='VALOR POR PL'!L11 | N12: =IF('VALOR POR PL'!I11="DIRETO",'VALOR POR PL'!L11,0)
B13: ='VALOR POR PL'!C12 | C13: ='VALOR POR PL'!D12 | D13: =IF(OR('VALOR POR PL'!I12<>"DIRETO",'CP RESUMO'!$C$6=""),"",IFERROR(INDEX('CP RESUMO'!$D$6:$BW$6,MATCH(DATE($D$5,12,1),'CP RESUMO'!$D$4:$BW$4,0))/100,"")) | E13: =IF('VALOR POR PL'!I12<>"DIRETO","",'SEGUROS'!$K$14) | F13: =SUMPRODUCT((YEAR('SEGUROS'!$B$5:$B$76)=$D$5)*('SEGUROS'!$C$5:$C$76+'SEGUROS'!$D$5:$D$76)) | G13: =SUMPRODUCT((YEAR('MODELO PARA BI'!$H$1:$CA$1)=$D$5)*'MODELO PARA BI'!$H$40:$CA$40) | H13: =IF(ISNUMBER($G$5),G13*$G$5,0) | I13: =IF($F$53=0,0,F13/$F$53) | J13: =IF('VALOR POR PL'!L12=0,0,SUMPRODUCT(('SEGUROS'!$B$5:$B$76<=DATE($D$5,12,1))*('SEGUROS'!$C$5:$C$76+'SEGUROS'!$D$5:$D$76))/'VALOR POR PL'!L12) | K13: {=IF(COUNTIF('CRONOGRAMA ATIVIDADES'!$M$5:$M$6004,B13)=0,"",IF(COUNTIFS('CRONOGRAMA ATIVIDADES'!$M$5:$M$6004,B13,'CRONOGRAMA ATIVIDADES'!$O$5:$O$6004,"CONCLUÍDA")=COUNTIF('CRONOGRAMA ATIVIDADES'!$M$5:$M$6004,B13),"Concluído (todas as "&COUNTIF('CRONOGRAMA ATIVIDADES'!$M$5:$M$6004,B13)&" atividades)",IF(COUNTIFS('CRONOGRAMA ATIVIDADES'!$M$5:$M$6004,B13,'CRONOGRAMA ATIVIDADES'!$O$5:$O$6004,"A INICIAR")=COUNTIF('CRONOGRAMA ATIVIDADES'!$M$5:$M$6004,B13),"Não iniciado · início previsto em "&CHOOSE(MONTH(_xlfn.MINIFS('CRONOGRAMA ATIVIDADES'!$F$5:$F$6004,'CRONOGRAMA ATIVIDADES'!$M$5:$M$6004,B13)),"jan","fev","mar","abr","mai","jun","jul","ago","set","out","nov","dez")&"/"&YEAR(_xlfn.MINIFS('CRONOGRAMA ATIVIDADES'!$F$5:$F$6004,'CRONOGRAMA ATIVIDADES'!$M$5:$M$6004,B13)),_xlfn.TEXTJOIN(" / ",TRUE,IF(('CRONOGRAMA ATIVIDADES'!$S$5:$S$304=B13)*('CRONOGRAMA ATIVIDADES'!$AA$5:$AA$304<>""),'CRONOGRAMA ATIVIDADES'!$AA$5:$AA$304,"")))))} | M13: ='VALOR POR PL'!L12 | N13: =IF('VALOR POR PL'!I12="DIRETO",'VALOR POR PL'!L12,0)
B14: ='VALOR POR PL'!C13 | C14: ='VALOR POR PL'!D13 | D14: =IF(OR('VALOR POR PL'!I13<>"DIRETO",'CP RESUMO'!$C$7=""),"",IFERROR(INDEX('CP RESUMO'!$D$7:$BW$7,MATCH(DATE($D$5,12,1),'CP RESUMO'!$D$4:$BW$4,0))/100,"")) | E14: =IF('VALOR POR PL'!I13<>"DIRETO","",'TAX. DIVERSAS'!$K$14) | F14: =SUMPRODUCT((YEAR('TAX. DIVERSAS'!$B$5:$B$76)=$D$5)*('TAX. DIVERSAS'!$C$5:$C$76+'TAX. DIVERSAS'!$D$5:$D$76)) | G14: =SUMPRODUCT((YEAR('MODELO PARA BI'!$H$1:$CA$1)=$D$5)*'MODELO PARA BI'!$H$50:$CA$50) | H14: =IF(ISNUMBER($G$5),G14*$G$5,0) | I14: =IF($F$53=0,0,F14/$F$53) | J14: =IF('VALOR POR PL'!L13=0,0,SUMPRODUCT(('TAX. DIVERSAS'!$B$5:$B$76<=DATE($D$5,12,1))*('TAX. DIVERSAS'!$C$5:$C$76+'TAX. DIVERSAS'!$D$5:$D$76))/'VALOR POR PL'!L13) | K14: {=IF(COUNTIF('CRONOGRAMA ATIVIDADES'!$M$5:$M$6004,B14)=0,"",IF(COUNTIFS('CRONOGRAMA ATIVIDADES'!$M$5:$M$6004,B14,'CRONOGRAMA ATIVIDADES'!$O$5:$O$6004,"CONCLUÍDA")=COUNTIF('CRONOGRAMA ATIVIDADES'!$M$5:$M$6004,B14),"Concluído (todas as "&COUNTIF('CRONOGRAMA ATIVIDADES'!$M$5:$M$6004,B14)&" atividades)",IF(COUNTIFS('CRONOGRAMA ATIVIDADES'!$M$5:$M$6004,B14,'CRONOGRAMA ATIVIDADES'!$O$5:$O$6004,"A INICIAR")=COUNTIF('CRONOGRAMA ATIVIDADES'!$M$5:$M$6004,B14),"Não iniciado · início previsto em "&CHOOSE(MONTH(_xlfn.MINIFS('CRONOGRAMA ATIVIDADES'!$F$5:$F$6004,'CRONOGRAMA ATIVIDADES'!$M$5:$M$6004,B14)),"jan","fev","mar","abr","mai","jun","jul","ago","set","out","nov","dez")&"/"&YEAR(_xlfn.MINIFS('CRONOGRAMA ATIVIDADES'!$F$5:$F$6004,'CRONOGRAMA ATIVIDADES'!$M$5:$M$6004,B14)),_xlfn.TEXTJOIN(" / ",TRUE,IF(('CRONOGRAMA ATIVIDADES'!$S$5:$S$304=B14)*('CRONOGRAMA ATIVIDADES'!$AA$5:$AA$304<>""),'CRONOGRAMA ATIVIDADES'!$AA$5:$AA$304,"")))))} | M14: ='VALOR POR PL'!L13 | N14: =IF('VALOR POR PL'!I13="DIRETO",'VALOR POR PL'!L13,0)
B15: ='VALOR POR PL'!C14 | C15: ='VALOR POR PL'!D14 | D15: =IF(OR('VALOR POR PL'!I14<>"DIRETO",'CP RESUMO'!$C$8=""),"",IFERROR(INDEX('CP RESUMO'!$D$8:$BW$8,MATCH(DATE($D$5,12,1),'CP RESUMO'!$D$4:$BW$4,0))/100,"")) | E15: =IF('VALOR POR PL'!I14<>"DIRETO","",'BARRACÃO DE OBRA'!$K$14) | F15: =SUMPRODUCT((YEAR('BARRACÃO DE OBRA'!$B$5:$B$76)=$D$5)*('BARRACÃO DE OBRA'!$C$5:$C$76+'BARRACÃO DE OBRA'!$D$5:$D$76)) | G15: =SUMPRODUCT((YEAR('MODELO PARA BI'!$H$1:$CA$1)=$D$5)*'MODELO PARA BI'!$H$3:$CA$3) | H15: =IF(ISNUMBER($G$5),G15*$G$5,0) | I15: =IF($F$53=0,0,F15/$F$53) | J15: =IF('VALOR POR PL'!L14=0,0,SUMPRODUCT(('BARRACÃO DE OBRA'!$B$5:$B$76<=DATE($D$5,12,1))*('BARRACÃO DE OBRA'!$C$5:$C$76+'BARRACÃO DE OBRA'!$D$5:$D$76))/'VALOR POR PL'!L14) | K15: {=IF(COUNTIF('CRONOGRAMA ATIVIDADES'!$M$5:$M$6004,B15)=0,"",IF(COUNTIFS('CRONOGRAMA ATIVIDADES'!$M$5:$M$6004,B15,'CRONOGRAMA ATIVIDADES'!$O$5:$O$6004,"CONCLUÍDA")=COUNTIF('CRONOGRAMA ATIVIDADES'!$M$5:$M$6004,B15),"Concluído (todas as "&COUNTIF('CRONOGRAMA ATIVIDADES'!$M$5:$M$6004,B15)&" atividades)",IF(COUNTIFS('CRONOGRAMA ATIVIDADES'!$M$5:$M$6004,B15,'CRONOGRAMA ATIVIDADES'!$O$5:$O$6004,"A INICIAR")=COUNTIF('CRONOGRAMA ATIVIDADES'!$M$5:$M$6004,B15),"Não iniciado · início previsto em "&CHOOSE(MONTH(_xlfn.MINIFS('CRONOGRAMA ATIVIDADES'!$F$5:$F$6004,'CRONOGRAMA ATIVIDADES'!$M$5:$M$6004,B15)),"jan","fev","mar","abr","mai","jun","jul","ago","set","out","nov","dez")&"/"&YEAR(_xlfn.MINIFS('CRONOGRAMA ATIVIDADES'!$F$5:$F$6004,'CRONOGRAMA ATIVIDADES'!$M$5:$M$6004,B15)),_xlfn.TEXTJOIN(" / ",TRUE,IF(('CRONOGRAMA ATIVIDADES'!$S$5:$S$304=B15)*('CRONOGRAMA ATIVIDADES'!$AA$5:$AA$304<>""),'CRONOGRAMA ATIVIDADES'!$AA$5:$AA$304,"")))))} | M15: ='VALOR POR PL'!L14 | N15: =IF('VALOR POR PL'!I14="DIRETO",'VALOR POR PL'!L14,0)
B16: ='VALOR POR PL'!C15 | C16: ='VALOR POR PL'!D15 | D16: =IF(OR('VALOR POR PL'!I15<>"DIRETO",'CP RESUMO'!$C$9=""),"",IFERROR(INDEX('CP RESUMO'!$D$9:$BW$9,MATCH(DATE($D$5,12,1),'CP RESUMO'!$D$4:$BW$4,0))/100,"")) | E16: =IF('VALOR POR PL'!I15<>"DIRETO","",'LIG. PROVISÓRIAS'!$K$14) | F16: =SUMPRODUCT((YEAR('LIG. PROVISÓRIAS'!$B$5:$B$76)=$D$5)*('LIG. PROVISÓRIAS'!$C$5:$C$76+'LIG. PROVISÓRIAS'!$D$5:$D$76)) | G16: =SUMPRODUCT((YEAR('MODELO PARA BI'!$H$1:$CA$1)=$D$5)*'MODELO PARA BI'!$H$42:$CA$42) | H16: =IF(ISNUMBER($G$5),G16*$G$5,0) | I16: =IF($F$53=0,0,F16/$F$53) | J16: =IF('VALOR POR PL'!L15=0,0,SUMPRODUCT(('LIG. PROVISÓRIAS'!$B$5:$B$76<=DATE($D$5,12,1))*('LIG. PROVISÓRIAS'!$C$5:$C$76+'LIG. PROVISÓRIAS'!$D$5:$D$76))/'VALOR POR PL'!L15) | K16: {=IF(COUNTIF('CRONOGRAMA ATIVIDADES'!$M$5:$M$6004,B16)=0,"",IF(COUNTIFS('CRONOGRAMA ATIVIDADES'!$M$5:$M$6004,B16,'CRONOGRAMA ATIVIDADES'!$O$5:$O$6004,"CONCLUÍDA")=COUNTIF('CRONOGRAMA ATIVIDADES'!$M$5:$M$6004,B16),"Concluído (todas as "&COUNTIF('CRONOGRAMA ATIVIDADES'!$M$5:$M$6004,B16)&" atividades)",IF(COUNTIFS('CRONOGRAMA ATIVIDADES'!$M$5:$M$6004,B16,'CRONOGRAMA ATIVIDADES'!$O$5:$O$6004,"A INICIAR")=COUNTIF('CRONOGRAMA ATIVIDADES'!$M$5:$M$6004,B16),"Não iniciado · início previsto em "&CHOOSE(MONTH(_xlfn.MINIFS('CRONOGRAMA ATIVIDADES'!$F$5:$F$6004,'CRONOGRAMA ATIVIDADES'!$M$5:$M$6004,B16)),"jan","fev","mar","abr","mai","jun","jul","ago","set","out","nov","dez")&"/"&YEAR(_xlfn.MINIFS('CRONOGRAMA ATIVIDADES'!$F$5:$F$6004,'CRONOGRAMA ATIVIDADES'!$M$5:$M$6004,B16)),_xlfn.TEXTJOIN(" / ",TRUE,IF(('CRONOGRAMA ATIVIDADES'!$S$5:$S$304=B16)*('CRONOGRAMA ATIVIDADES'!$AA$5:$AA$304<>""),'CRONOGRAMA ATIVIDADES'!$AA$5:$AA$304,"")))))} | M16: ='VALOR POR PL'!L15 | N16: =IF('VALOR POR PL'!I15="DIRETO",'VALOR POR PL'!L15,0)
B17: ='VALOR POR PL'!C16 | C17: ='VALOR POR PL'!D16 | D17: =IF(OR('VALOR POR PL'!I16<>"DIRETO",'CP RESUMO'!$C$10=""),"",IFERROR(INDEX('CP RESUMO'!$D$10:$BW$10,MATCH(DATE($D$5,12,1),'CP RESUMO'!$D$4:$BW$4,0))/100,"")) | E17: =IF('VALOR POR PL'!I16<>"DIRETO","",'CONSUMOS'!$K$14) | F17: =SUMPRODUCT((YEAR('CONSUMOS'!$B$5:$B$76)=$D$5)*('CONSUMOS'!$C$5:$C$76+'CONSUMOS'!$D$5:$D$76)) | G17: =SUMPRODUCT((YEAR('MODELO PARA BI'!$H$1:$CA$1)=$D$5)*'MODELO PARA BI'!$H$5:$CA$5) | H17: =IF(ISNUMBER($G$5),G17*$G$5,0) | I17: =IF($F$53=0,0,F17/$F$53) | J17: =IF('VALOR POR PL'!L16=0,0,SUMPRODUCT(('CONSUMOS'!$B$5:$B$76<=DATE($D$5,12,1))*('CONSUMOS'!$C$5:$C$76+'CONSUMOS'!$D$5:$D$76))/'VALOR POR PL'!L16) | K17: {=IF(COUNTIF('CRONOGRAMA ATIVIDADES'!$M$5:$M$6004,B17)=0,"",IF(COUNTIFS('CRONOGRAMA ATIVIDADES'!$M$5:$M$6004,B17,'CRONOGRAMA ATIVIDADES'!$O$5:$O$6004,"CONCLUÍDA")=COUNTIF('CRONOGRAMA ATIVIDADES'!$M$5:$M$6004,B17),"Concluído (todas as "&COUNTIF('CRONOGRAMA ATIVIDADES'!$M$5:$M$6004,B17)&" atividades)",IF(COUNTIFS('CRONOGRAMA ATIVIDADES'!$M$5:$M$6004,B17,'CRONOGRAMA ATIVIDADES'!$O$5:$O$6004,"A INICIAR")=COUNTIF('CRONOGRAMA ATIVIDADES'!$M$5:$M$6004,B17),"Não iniciado · início previsto em "&CHOOSE(MONTH(_xlfn.MINIFS('CRONOGRAMA ATIVIDADES'!$F$5:$F$6004,'CRONOGRAMA ATIVIDADES'!$M$5:$M$6004,B17)),"jan","fev","mar","abr","mai","jun","jul","ago","set","out","nov","dez")&"/"&YEAR(_xlfn.MINIFS('CRONOGRAMA ATIVIDADES'!$F$5:$F$6004,'CRONOGRAMA ATIVIDADES'!$M$5:$M$6004,B17)),_xlfn.TEXTJOIN(" / ",TRUE,IF(('CRONOGRAMA ATIVIDADES'!$S$5:$S$304=B17)*('CRONOGRAMA ATIVIDADES'!$AA$5:$AA$304<>""),'CRONOGRAMA ATIVIDADES'!$AA$5:$AA$304,"")))))} | M17: ='VALOR POR PL'!L16 | N17: =IF('VALOR POR PL'!I16="DIRETO",'VALOR POR PL'!L16,0)
B18: ='VALOR POR PL'!C17 | C18: ='VALOR POR PL'!D17 | D18: =IF(OR('VALOR POR PL'!I17<>"DIRETO",'CP RESUMO'!$C$11=""),"",IFERROR(INDEX('CP RESUMO'!$D$11:$BW$11,MATCH(DATE($D$5,12,1),'CP RESUMO'!$D$4:$BW$4,0))/100,"")) | E18: =IF('VALOR POR PL'!I17<>"DIRETO","",'DIVERSOS'!$K$14) | F18: =SUMPRODUCT((YEAR('DIVERSOS'!$B$5:$B$76)=$D$5)*('DIVERSOS'!$C$5:$C$76+'DIVERSOS'!$D$5:$D$76)) | G18: =SUMPRODUCT((YEAR('MODELO PARA BI'!$H$1:$CA$1)=$D$5)*'MODELO PARA BI'!$H$9:$CA$9) | H18: =IF(ISNUMBER($G$5),G18*$G$5,0) | I18: =IF($F$53=0,0,F18/$F$53) | J18: =IF('VALOR POR PL'!L17=0,0,SUMPRODUCT(('DIVERSOS'!$B$5:$B$76<=DATE($D$5,12,1))*('DIVERSOS'!$C$5:$C$76+'DIVERSOS'!$D$5:$D$76))/'VALOR POR PL'!L17) | K18: {=IF(COUNTIF('CRONOGRAMA ATIVIDADES'!$M$5:$M$6004,B18)=0,"",IF(COUNTIFS('CRONOGRAMA ATIVIDADES'!$M$5:$M$6004,B18,'CRONOGRAMA ATIVIDADES'!$O$5:$O$6004,"CONCLUÍDA")=COUNTIF('CRONOGRAMA ATIVIDADES'!$M$5:$M$6004,B18),"Concluído (todas as "&COUNTIF('CRONOGRAMA ATIVIDADES'!$M$5:$M$6004,B18)&" atividades)",IF(COUNTIFS('CRONOGRAMA ATIVIDADES'!$M$5:$M$6004,B18,'CRONOGRAMA ATIVIDADES'!$O$5:$O$6004,"A INICIAR")=COUNTIF('CRONOGRAMA ATIVIDADES'!$M$5:$M$6004,B18),"Não iniciado · início previsto em "&CHOOSE(MONTH(_xlfn.MINIFS('CRONOGRAMA ATIVIDADES'!$F$5:$F$6004,'CRONOGRAMA ATIVIDADES'!$M$5:$M$6004,B18)),"jan","fev","mar","abr","mai","jun","jul","ago","set","out","nov","dez")&"/"&YEAR(_xlfn.MINIFS('CRONOGRAMA ATIVIDADES'!$F$5:$F$6004,'CRONOGRAMA ATIVIDADES'!$M$5:$M$6004,B18)),_xlfn.TEXTJOIN(" / ",TRUE,IF(('CRONOGRAMA ATIVIDADES'!$S$5:$S$304=B18)*('CRONOGRAMA ATIVIDADES'!$AA$5:$AA$304<>""),'CRONOGRAMA ATIVIDADES'!$AA$5:$AA$304,"")))))} | M18: ='VALOR POR PL'!L17 | N18: =IF('VALOR POR PL'!I17="DIRETO",'VALOR POR PL'!L17,0)
B19: ='VALOR POR PL'!C18 | C19: ='VALOR POR PL'!D18 | D19: =IF(OR('VALOR POR PL'!I18<>"DIRETO",'CP RESUMO'!$C$12=""),"",IFERROR(INDEX('CP RESUMO'!$D$12:$BW$12,MATCH(DATE($D$5,12,1),'CP RESUMO'!$D$4:$BW$4,0))/100,"")) | E19: =IF('VALOR POR PL'!I18<>"DIRETO","",'TRANSPORTES'!$K$14) | F19: =SUMPRODUCT((YEAR('TRANSPORTES'!$B$5:$B$76)=$D$5)*('TRANSPORTES'!$C$5:$C$76+'TRANSPORTES'!$D$5:$D$76)) | G19: =SUMPRODUCT((YEAR('MODELO PARA BI'!$H$1:$CA$1)=$D$5)*'MODELO PARA BI'!$H$46:$CA$46) | H19: =IF(ISNUMBER($G$5),G19*$G$5,0) | I19: =IF($F$53=0,0,F19/$F$53) | J19: =IF('VALOR POR PL'!L18=0,0,SUMPRODUCT(('TRANSPORTES'!$B$5:$B$76<=DATE($D$5,12,1))*('TRANSPORTES'!$C$5:$C$76+'TRANSPORTES'!$D$5:$D$76))/'VALOR POR PL'!L18) | K19: {=IF(COUNTIF('CRONOGRAMA ATIVIDADES'!$M$5:$M$6004,B19)=0,"",IF(COUNTIFS('CRONOGRAMA ATIVIDADES'!$M$5:$M$6004,B19,'CRONOGRAMA ATIVIDADES'!$O$5:$O$6004,"CONCLUÍDA")=COUNTIF('CRONOGRAMA ATIVIDADES'!$M$5:$M$6004,B19),"Concluído (todas as "&COUNTIF('CRONOGRAMA ATIVIDADES'!$M$5:$M$6004,B19)&" atividades)",IF(COUNTIFS('CRONOGRAMA ATIVIDADES'!$M$5:$M$6004,B19,'CRONOGRAMA ATIVIDADES'!$O$5:$O$6004,"A INICIAR")=COUNTIF('CRONOGRAMA ATIVIDADES'!$M$5:$M$6004,B19),"Não iniciado · início previsto em "&CHOOSE(MONTH(_xlfn.MINIFS('CRONOGRAMA ATIVIDADES'!$F$5:$F$6004,'CRONOGRAMA ATIVIDADES'!$M$5:$M$6004,B19)),"jan","fev","mar","abr","mai","jun","jul","ago","set","out","nov","dez")&"/"&YEAR(_xlfn.MINIFS('CRONOGRAMA ATIVIDADES'!$F$5:$F$6004,'CRONOGRAMA ATIVIDADES'!$M$5:$M$6004,B19)),_xlfn.TEXTJOIN(" / ",TRUE,IF(('CRONOGRAMA ATIVIDADES'!$S$5:$S$304=B19)*('CRONOGRAMA ATIVIDADES'!$AA$5:$AA$304<>""),'CRONOGRAMA ATIVIDADES'!$AA$5:$AA$304,"")))))} | M19: ='VALOR POR PL'!L18 | N19: =IF('VALOR POR PL'!I18="DIRETO",'VALOR POR PL'!L18,0)
B20: ='VALOR POR PL'!C19 | C20: ='VALOR POR PL'!D19 | D20: =IF(OR('VALOR POR PL'!I19<>"DIRETO",'CP RESUMO'!$C$13=""),"",IFERROR(INDEX('CP RESUMO'!$D$13:$BW$13,MATCH(DATE($D$5,12,1),'CP RESUMO'!$D$4:$BW$4,0))/100,"")) | E20: =IF('VALOR POR PL'!I19<>"DIRETO","",'CONSULTORIAS'!$K$14) | F20: =SUMPRODUCT((YEAR('CONSULTORIAS'!$B$5:$B$76)=$D$5)*('CONSULTORIAS'!$C$5:$C$76+'CONSULTORIAS'!$D$5:$D$76)) | G20: =SUMPRODUCT((YEAR('MODELO PARA BI'!$H$1:$CA$1)=$D$5)*'MODELO PARA BI'!$H$4:$CA$4) | H20: =IF(ISNUMBER($G$5),G20*$G$5,0) | I20: =IF($F$53=0,0,F20/$F$53) | J20: =IF('VALOR POR PL'!L19=0,0,SUMPRODUCT(('CONSULTORIAS'!$B$5:$B$76<=DATE($D$5,12,1))*('CONSULTORIAS'!$C$5:$C$76+'CONSULTORIAS'!$D$5:$D$76))/'VALOR POR PL'!L19) | K20: {=IF(COUNTIF('CRONOGRAMA ATIVIDADES'!$M$5:$M$6004,B20)=0,"",IF(COUNTIFS('CRONOGRAMA ATIVIDADES'!$M$5:$M$6004,B20,'CRONOGRAMA ATIVIDADES'!$O$5:$O$6004,"CONCLUÍDA")=COUNTIF('CRONOGRAMA ATIVIDADES'!$M$5:$M$6004,B20),"Concluído (todas as "&COUNTIF('CRONOGRAMA ATIVIDADES'!$M$5:$M$6004,B20)&" atividades)",IF(COUNTIFS('CRONOGRAMA ATIVIDADES'!$M$5:$M$6004,B20,'CRONOGRAMA ATIVIDADES'!$O$5:$O$6004,"A INICIAR")=COUNTIF('CRONOGRAMA ATIVIDADES'!$M$5:$M$6004,B20),"Não iniciado · início previsto em "&CHOOSE(MONTH(_xlfn.MINIFS('CRONOGRAMA ATIVIDADES'!$F$5:$F$6004,'CRONOGRAMA ATIVIDADES'!$M$5:$M$6004,B20)),"jan","fev","mar","abr","mai","jun","jul","ago","set","out","nov","dez")&"/"&YEAR(_xlfn.MINIFS('CRONOGRAMA ATIVIDADES'!$F$5:$F$6004,'CRONOGRAMA ATIVIDADES'!$M$5:$M$6004,B20)),_xlfn.TEXTJOIN(" / ",TRUE,IF(('CRONOGRAMA ATIVIDADES'!$S$5:$S$304=B20)*('CRONOGRAMA ATIVIDADES'!$AA$5:$AA$304<>""),'CRONOGRAMA ATIVIDADES'!$AA$5:$AA$304,"")))))} | M20: ='VALOR POR PL'!L19 | N20: =IF('VALOR POR PL'!I19="DIRETO",'VALOR POR PL'!L19,0)
B21: ='VALOR POR PL'!C20 | C21: ='VALOR POR PL'!D20 | D21: =IF(OR('VALOR POR PL'!I20<>"DIRETO",'CP RESUMO'!$C$14=""),"",IFERROR(INDEX('CP RESUMO'!$D$14:$BW$14,MATCH(DATE($D$5,12,1),'CP RESUMO'!$D$4:$BW$4,0))/100,"")) | E21: =IF('VALOR POR PL'!I20<>"DIRETO","",'MDO'!$K$14) | F21: =SUMPRODUCT((YEAR('MDO'!$B$5:$B$76)=$D$5)*('MDO'!$C$5:$C$76+'MDO'!$D$5:$D$76)) | G21: =SUMPRODUCT((YEAR('MODELO PARA BI'!$H$1:$CA$1)=$D$5)*'MODELO PARA BI'!$H$49:$CA$49) | H21: =IF(ISNUMBER($G$5),G21*$G$5,0) | I21: =IF($F$53=0,0,F21/$F$53) | J21: =IF('VALOR POR PL'!L20=0,0,SUMPRODUCT(('MDO'!$B$5:$B$76<=DATE($D$5,12,1))*('MDO'!$C$5:$C$76+'MDO'!$D$5:$D$76))/'VALOR POR PL'!L20) | K21: {=IF(COUNTIF('CRONOGRAMA ATIVIDADES'!$M$5:$M$6004,B21)=0,"",IF(COUNTIFS('CRONOGRAMA ATIVIDADES'!$M$5:$M$6004,B21,'CRONOGRAMA ATIVIDADES'!$O$5:$O$6004,"CONCLUÍDA")=COUNTIF('CRONOGRAMA ATIVIDADES'!$M$5:$M$6004,B21),"Concluído (todas as "&COUNTIF('CRONOGRAMA ATIVIDADES'!$M$5:$M$6004,B21)&" atividades)",IF(COUNTIFS('CRONOGRAMA ATIVIDADES'!$M$5:$M$6004,B21,'CRONOGRAMA ATIVIDADES'!$O$5:$O$6004,"A INICIAR")=COUNTIF('CRONOGRAMA ATIVIDADES'!$M$5:$M$6004,B21),"Não iniciado · início previsto em "&CHOOSE(MONTH(_xlfn.MINIFS('CRONOGRAMA ATIVIDADES'!$F$5:$F$6004,'CRONOGRAMA ATIVIDADES'!$M$5:$M$6004,B21)),"jan","fev","mar","abr","mai","jun","jul","ago","set","out","nov","dez")&"/"&YEAR(_xlfn.MINIFS('CRONOGRAMA ATIVIDADES'!$F$5:$F$6004,'CRONOGRAMA ATIVIDADES'!$M$5:$M$6004,B21)),_xlfn.TEXTJOIN(" / ",TRUE,IF(('CRONOGRAMA ATIVIDADES'!$S$5:$S$304=B21)*('CRONOGRAMA ATIVIDADES'!$AA$5:$AA$304<>""),'CRONOGRAMA ATIVIDADES'!$AA$5:$AA$304,"")))))} | M21: ='VALOR POR PL'!L20 | N21: =IF('VALOR POR PL'!I20="DIRETO",'VALOR POR PL'!L20,0)
B22: ='VALOR POR PL'!C21 | C22: ='VALOR POR PL'!D21 | D22: =IF(OR('VALOR POR PL'!I21<>"DIRETO",'CP RESUMO'!$C$15=""),"",IFERROR(INDEX('CP RESUMO'!$D$15:$BW$15,MATCH(DATE($D$5,12,1),'CP RESUMO'!$D$4:$BW$4,0))/100,"")) | E22: =IF('VALOR POR PL'!I21<>"DIRETO","",'EQUIP E FER'!$K$14) | F22: =SUMPRODUCT((YEAR('EQUIP E FER'!$B$5:$B$76)=$D$5)*('EQUIP E FER'!$C$5:$C$76+'EQUIP E FER'!$D$5:$D$76)) | G22: =SUMPRODUCT((YEAR('MODELO PARA BI'!$H$1:$CA$1)=$D$5)*'MODELO PARA BI'!$H$11:$CA$11) | H22: =IF(ISNUMBER($G$5),G22*$G$5,0) | I22: =IF($F$53=0,0,F22/$F$53) | J22: =IF('VALOR POR PL'!L21=0,0,SUMPRODUCT(('EQUIP E FER'!$B$5:$B$76<=DATE($D$5,12,1))*('EQUIP E FER'!$C$5:$C$76+'EQUIP E FER'!$D$5:$D$76))/'VALOR POR PL'!L21) | K22: {=IF(COUNTIF('CRONOGRAMA ATIVIDADES'!$M$5:$M$6004,B22)=0,"",IF(COUNTIFS('CRONOGRAMA ATIVIDADES'!$M$5:$M$6004,B22,'CRONOGRAMA ATIVIDADES'!$O$5:$O$6004,"CONCLUÍDA")=COUNTIF('CRONOGRAMA ATIVIDADES'!$M$5:$M$6004,B22),"Concluído (todas as "&COUNTIF('CRONOGRAMA ATIVIDADES'!$M$5:$M$6004,B22)&" atividades)",IF(COUNTIFS('CRONOGRAMA ATIVIDADES'!$M$5:$M$6004,B22,'CRONOGRAMA ATIVIDADES'!$O$5:$O$6004,"A INICIAR")=COUNTIF('CRONOGRAMA ATIVIDADES'!$M$5:$M$6004,B22),"Não iniciado · início previsto em "&CHOOSE(MONTH(_xlfn.MINIFS('CRONOGRAMA ATIVIDADES'!$F$5:$F$6004,'CRONOGRAMA ATIVIDADES'!$M$5:$M$6004,B22)),"jan","fev","mar","abr","mai","jun","jul","ago","set","out","nov","dez")&"/"&YEAR(_xlfn.MINIFS('CRONOGRAMA ATIVIDADES'!$F$5:$F$6004,'CRONOGRAMA ATIVIDADES'!$M$5:$M$6004,B22)),_xlfn.TEXTJOIN(" / ",TRUE,IF(('CRONOGRAMA ATIVIDADES'!$S$5:$S$304=B22)*('CRONOGRAMA ATIVIDADES'!$AA$5:$AA$304<>""),'CRONOGRAMA ATIVIDADES'!$AA$5:$AA$304,"")))))} | M22: ='VALOR POR PL'!L21 | N22: =IF('VALOR POR PL'!I21="DIRETO",'VALOR POR PL'!L21,0)
B23: 01 a 11 | C23: INDIRETOS | D23: =IFERROR(SUMPRODUCT(D12:D22,N12:N22)/SUMPRODUCT(ISNUMBER(D12:D22)*N12:N22),"") | E23: =IFERROR(SUMPRODUCT(E12:E22,N12:N22)/SUMPRODUCT(ISNUMBER(E12:E22)*N12:N22),"") | F23: =SUM(F12:F22) | G23: =SUM(G12:G22) | H23: =SUM(H12:H22) | I23: =IF($F$53=0,0,F23/$F$53) | J23: =IFERROR(SUMPRODUCT(J12:J22,M12:M22)/SUM(M12:M22),0) | M23: =SUM(M12:M22) | N23: =SUM(N12:N22)
B24: ='VALOR POR PL'!C22 | C24: ='VALOR POR PL'!D22 | D24: =IF(OR('VALOR POR PL'!I22<>"DIRETO",'CP RESUMO'!$C$16=""),"",IFERROR(INDEX('CP RESUMO'!$D$16:$BW$16,MATCH(DATE($D$5,12,1),'CP RESUMO'!$D$4:$BW$4,0))/100,"")) | E24: =IF('VALOR POR PL'!I22<>"DIRETO","",'SERV. INICIAIS'!$K$14) | F24: =SUMPRODUCT((YEAR('SERV. INICIAIS'!$B$5:$B$76)=$D$5)*('SERV. INICIAIS'!$C$5:$C$76+'SERV. INICIAIS'!$D$5:$D$76)) | G24: =SUMPRODUCT((YEAR('MODELO PARA BI'!$H$1:$CA$1)=$D$5)*'MODELO PARA BI'!$H$52:$CA$52) | H24: =IF(ISNUMBER($G$5),G24*$G$5,0) | I24: =IF($F$53=0,0,F24/$F$53) | J24: =IF('VALOR POR PL'!L22=0,0,SUMPRODUCT(('SERV. INICIAIS'!$B$5:$B$76<=DATE($D$5,12,1))*('SERV. INICIAIS'!$C$5:$C$76+'SERV. INICIAIS'!$D$5:$D$76))/'VALOR POR PL'!L22) | K24: {=IF(COUNTIF('CRONOGRAMA ATIVIDADES'!$M$5:$M$6004,B24)=0,"",IF(COUNTIFS('CRONOGRAMA ATIVIDADES'!$M$5:$M$6004,B24,'CRONOGRAMA ATIVIDADES'!$O$5:$O$6004,"CONCLUÍDA")=COUNTIF('CRONOGRAMA ATIVIDADES'!$M$5:$M$6004,B24),"Concluído (todas as "&COUNTIF('CRONOGRAMA ATIVIDADES'!$M$5:$M$6004,B24)&" atividades)",IF(COUNTIFS('CRONOGRAMA ATIVIDADES'!$M$5:$M$6004,B24,'CRONOGRAMA ATIVIDADES'!$O$5:$O$6004,"A INICIAR")=COUNTIF('CRONOGRAMA ATIVIDADES'!$M$5:$M$6004,B24),"Não iniciado · início previsto em "&CHOOSE(MONTH(_xlfn.MINIFS('CRONOGRAMA ATIVIDADES'!$F$5:$F$6004,'CRONOGRAMA ATIVIDADES'!$M$5:$M$6004,B24)),"jan","fev","mar","abr","mai","jun","jul","ago","set","out","nov","dez")&"/"&YEAR(_xlfn.MINIFS('CRONOGRAMA ATIVIDADES'!$F$5:$F$6004,'CRONOGRAMA ATIVIDADES'!$M$5:$M$6004,B24)),_xlfn.TEXTJOIN(" / ",TRUE,IF(('CRONOGRAMA ATIVIDADES'!$S$5:$S$304=B24)*('CRONOGRAMA ATIVIDADES'!$AA$5:$AA$304<>""),'CRONOGRAMA ATIVIDADES'!$AA$5:$AA$304,"")))))} | M24: ='VALOR POR PL'!L22 | N24: =IF('VALOR POR PL'!I22="DIRETO",'VALOR POR PL'!L22,0)
B25: ='VALOR POR PL'!C23 | C25: ='VALOR POR PL'!D23 | D25: =IF(OR('VALOR POR PL'!I23<>"DIRETO",'CP RESUMO'!$C$17=""),"",IFERROR(INDEX('CP RESUMO'!$D$17:$BW$17,MATCH(DATE($D$5,12,1),'CP RESUMO'!$D$4:$BW$4,0))/100,"")) | E25: =IF('VALOR POR PL'!I23<>"DIRETO","",'CONTENÇÃO'!$K$14) | F25: =SUMPRODUCT((YEAR('CONTENÇÃO'!$B$5:$B$76)=$D$5)*('CONTENÇÃO'!$C$5:$C$76+'CONTENÇÃO'!$D$5:$D$76)) | G25: =SUMPRODUCT((YEAR('MODELO PARA BI'!$H$1:$CA$1)=$D$5)*'MODELO PARA BI'!$H$6:$CA$6) | H25: =IF(ISNUMBER($G$5),G25*$G$5,0) | I25: =IF($F$53=0,0,F25/$F$53) | J25: =IF('VALOR POR PL'!L23=0,0,SUMPRODUCT(('CONTENÇÃO'!$B$5:$B$76<=DATE($D$5,12,1))*('CONTENÇÃO'!$C$5:$C$76+'CONTENÇÃO'!$D$5:$D$76))/'VALOR POR PL'!L23) | K25: {=IF(COUNTIF('CRONOGRAMA ATIVIDADES'!$M$5:$M$6004,B25)=0,"",IF(COUNTIFS('CRONOGRAMA ATIVIDADES'!$M$5:$M$6004,B25,'CRONOGRAMA ATIVIDADES'!$O$5:$O$6004,"CONCLUÍDA")=COUNTIF('CRONOGRAMA ATIVIDADES'!$M$5:$M$6004,B25),"Concluído (todas as "&COUNTIF('CRONOGRAMA ATIVIDADES'!$M$5:$M$6004,B25)&" atividades)",IF(COUNTIFS('CRONOGRAMA ATIVIDADES'!$M$5:$M$6004,B25,'CRONOGRAMA ATIVIDADES'!$O$5:$O$6004,"A INICIAR")=COUNTIF('CRONOGRAMA ATIVIDADES'!$M$5:$M$6004,B25),"Não iniciado · início previsto em "&CHOOSE(MONTH(_xlfn.MINIFS('CRONOGRAMA ATIVIDADES'!$F$5:$F$6004,'CRONOGRAMA ATIVIDADES'!$M$5:$M$6004,B25)),"jan","fev","mar","abr","mai","jun","jul","ago","set","out","nov","dez")&"/"&YEAR(_xlfn.MINIFS('CRONOGRAMA ATIVIDADES'!$F$5:$F$6004,'CRONOGRAMA ATIVIDADES'!$M$5:$M$6004,B25)),_xlfn.TEXTJOIN(" / ",TRUE,IF(('CRONOGRAMA ATIVIDADES'!$S$5:$S$304=B25)*('CRONOGRAMA ATIVIDADES'!$AA$5:$AA$304<>""),'CRONOGRAMA ATIVIDADES'!$AA$5:$AA$304,"")))))} | M25: ='VALOR POR PL'!L23 | N25: =IF('VALOR POR PL'!I23="DIRETO",'VALOR POR PL'!L23,0)
